10/08/21 (20:51:17) | ERROR: The read operation timed out
Traceback (most recent call last):
  File "/usr/local/bin/bpytop", line 5009, in _checker
    with urllib.request.urlopen("https://github.com/aristocratos/bpytop/raw/master/bpytop.py", timeout=5) as source: # type: ignore
  File "/usr/local/Cellar/python@3.9/3.9.6/Frameworks/Python.framework/Versions/3.9/lib/python3.9/urllib/request.py", line 214, in urlopen
    return opener.open(url, data, timeout)
  File "/usr/local/Cellar/python@3.9/3.9.6/Frameworks/Python.framework/Versions/3.9/lib/python3.9/urllib/request.py", line 517, in open
    response = self._open(req, data)
  File "/usr/local/Cellar/python@3.9/3.9.6/Frameworks/Python.framework/Versions/3.9/lib/python3.9/urllib/request.py", line 534, in _open
    result = self._call_chain(self.handle_open, protocol, protocol +
  File "/usr/local/Cellar/python@3.9/3.9.6/Frameworks/Python.framework/Versions/3.9/lib/python3.9/urllib/request.py", line 494, in _call_chain
    result = func(*args)
  File "/usr/local/Cellar/python@3.9/3.9.6/Frameworks/Python.framework/Versions/3.9/lib/python3.9/urllib/request.py", line 1389, in https_open
    return self.do_open(http.client.HTTPSConnection, req,
  File "/usr/local/Cellar/python@3.9/3.9.6/Frameworks/Python.framework/Versions/3.9/lib/python3.9/urllib/request.py", line 1350, in do_open
    r = h.getresponse()
  File "/usr/local/Cellar/python@3.9/3.9.6/Frameworks/Python.framework/Versions/3.9/lib/python3.9/http/client.py", line 1349, in getresponse
    response.begin()
  File "/usr/local/Cellar/python@3.9/3.9.6/Frameworks/Python.framework/Versions/3.9/lib/python3.9/http/client.py", line 316, in begin
    version, status, reason = self._read_status()
  File "/usr/local/Cellar/python@3.9/3.9.6/Frameworks/Python.framework/Versions/3.9/lib/python3.9/http/client.py", line 277, in _read_status
    line = str(self.fp.readline(_MAXLINE + 1), "iso-8859-1")
  File "/usr/local/Cellar/python@3.9/3.9.6/Frameworks/Python.framework/Versions/3.9/lib/python3.9/socket.py", line 704, in readinto
    return self._sock.recv_into(b)
  File "/usr/local/Cellar/python@3.9/3.9.6/Frameworks/Python.framework/Versions/3.9/lib/python3.9/ssl.py", line 1241, in recv_into
    return self.read(nbytes, buffer)
  File "/usr/local/Cellar/python@3.9/3.9.6/Frameworks/Python.framework/Versions/3.9/lib/python3.9/ssl.py", line 1099, in read
    return self._sslobj.read(len, buffer)
socket.timeout: The read operation timed out
10/08/21 (20:53:59) | ERROR: <urlopen error timed out>
Traceback (most recent call last):
  File "/usr/local/Cellar/python@3.9/3.9.6/Frameworks/Python.framework/Versions/3.9/lib/python3.9/urllib/request.py", line 1346, in do_open
    h.request(req.get_method(), req.selector, req.data, headers,
  File "/usr/local/Cellar/python@3.9/3.9.6/Frameworks/Python.framework/Versions/3.9/lib/python3.9/http/client.py", line 1257, in request
    self._send_request(method, url, body, headers, encode_chunked)
  File "/usr/local/Cellar/python@3.9/3.9.6/Frameworks/Python.framework/Versions/3.9/lib/python3.9/http/client.py", line 1303, in _send_request
    self.endheaders(body, encode_chunked=encode_chunked)
  File "/usr/local/Cellar/python@3.9/3.9.6/Frameworks/Python.framework/Versions/3.9/lib/python3.9/http/client.py", line 1252, in endheaders
    self._send_output(message_body, encode_chunked=encode_chunked)
  File "/usr/local/Cellar/python@3.9/3.9.6/Frameworks/Python.framework/Versions/3.9/lib/python3.9/http/client.py", line 1012, in _send_output
    self.send(msg)
  File "/usr/local/Cellar/python@3.9/3.9.6/Frameworks/Python.framework/Versions/3.9/lib/python3.9/http/client.py", line 952, in send
    self.connect()
  File "/usr/local/Cellar/python@3.9/3.9.6/Frameworks/Python.framework/Versions/3.9/lib/python3.9/http/client.py", line 1419, in connect
    super().connect()
  File "/usr/local/Cellar/python@3.9/3.9.6/Frameworks/Python.framework/Versions/3.9/lib/python3.9/http/client.py", line 923, in connect
    self.sock = self._create_connection(
  File "/usr/local/Cellar/python@3.9/3.9.6/Frameworks/Python.framework/Versions/3.9/lib/python3.9/socket.py", line 843, in create_connection
    raise err
  File "/usr/local/Cellar/python@3.9/3.9.6/Frameworks/Python.framework/Versions/3.9/lib/python3.9/socket.py", line 831, in create_connection
    sock.connect(sa)
socket.timeout: timed out

During handling of the above exception, another exception occurred:

Traceback (most recent call last):
  File "/usr/local/bin/bpytop", line 5009, in _checker
    with urllib.request.urlopen("https://github.com/aristocratos/bpytop/raw/master/bpytop.py", timeout=5) as source: # type: ignore
  File "/usr/local/Cellar/python@3.9/3.9.6/Frameworks/Python.framework/Versions/3.9/lib/python3.9/urllib/request.py", line 214, in urlopen
    return opener.open(url, data, timeout)
  File "/usr/local/Cellar/python@3.9/3.9.6/Frameworks/Python.framework/Versions/3.9/lib/python3.9/urllib/request.py", line 517, in open
    response = self._open(req, data)
  File "/usr/local/Cellar/python@3.9/3.9.6/Frameworks/Python.framework/Versions/3.9/lib/python3.9/urllib/request.py", line 534, in _open
    result = self._call_chain(self.handle_open, protocol, protocol +
  File "/usr/local/Cellar/python@3.9/3.9.6/Frameworks/Python.framework/Versions/3.9/lib/python3.9/urllib/request.py", line 494, in _call_chain
    result = func(*args)
  File "/usr/local/Cellar/python@3.9/3.9.6/Frameworks/Python.framework/Versions/3.9/lib/python3.9/urllib/request.py", line 1389, in https_open
    return self.do_open(http.client.HTTPSConnection, req,
  File "/usr/local/Cellar/python@3.9/3.9.6/Frameworks/Python.framework/Versions/3.9/lib/python3.9/urllib/request.py", line 1349, in do_open
    raise URLError(err)
urllib.error.URLError: <urlopen error timed out>
10/08/21 (21:18:41) | ERROR: The read operation timed out
Traceback (most recent call last):
  File "/usr/local/bin/bpytop", line 5009, in _checker
    with urllib.request.urlopen("https://github.com/aristocratos/bpytop/raw/master/bpytop.py", timeout=5) as source: # type: ignore
  File "/usr/local/Cellar/python@3.9/3.9.6/Frameworks/Python.framework/Versions/3.9/lib/python3.9/urllib/request.py", line 214, in urlopen
    return opener.open(url, data, timeout)
  File "/usr/local/Cellar/python@3.9/3.9.6/Frameworks/Python.framework/Versions/3.9/lib/python3.9/urllib/request.py", line 517, in open
    response = self._open(req, data)
  File "/usr/local/Cellar/python@3.9/3.9.6/Frameworks/Python.framework/Versions/3.9/lib/python3.9/urllib/request.py", line 534, in _open
    result = self._call_chain(self.handle_open, protocol, protocol +
  File "/usr/local/Cellar/python@3.9/3.9.6/Frameworks/Python.framework/Versions/3.9/lib/python3.9/urllib/request.py", line 494, in _call_chain
    result = func(*args)
  File "/usr/local/Cellar/python@3.9/3.9.6/Frameworks/Python.framework/Versions/3.9/lib/python3.9/urllib/request.py", line 1389, in https_open
    return self.do_open(http.client.HTTPSConnection, req,
  File "/usr/local/Cellar/python@3.9/3.9.6/Frameworks/Python.framework/Versions/3.9/lib/python3.9/urllib/request.py", line 1350, in do_open
    r = h.getresponse()
  File "/usr/local/Cellar/python@3.9/3.9.6/Frameworks/Python.framework/Versions/3.9/lib/python3.9/http/client.py", line 1349, in getresponse
    response.begin()
  File "/usr/local/Cellar/python@3.9/3.9.6/Frameworks/Python.framework/Versions/3.9/lib/python3.9/http/client.py", line 316, in begin
    version, status, reason = self._read_status()
  File "/usr/local/Cellar/python@3.9/3.9.6/Frameworks/Python.framework/Versions/3.9/lib/python3.9/http/client.py", line 277, in _read_status
    line = str(self.fp.readline(_MAXLINE + 1), "iso-8859-1")
  File "/usr/local/Cellar/python@3.9/3.9.6/Frameworks/Python.framework/Versions/3.9/lib/python3.9/socket.py", line 704, in readinto
    return self._sock.recv_into(b)
  File "/usr/local/Cellar/python@3.9/3.9.6/Frameworks/Python.framework/Versions/3.9/lib/python3.9/ssl.py", line 1241, in recv_into
    return self.read(nbytes, buffer)
  File "/usr/local/Cellar/python@3.9/3.9.6/Frameworks/Python.framework/Versions/3.9/lib/python3.9/ssl.py", line 1099, in read
    return self._sslobj.read(len, buffer)
socket.timeout: The read operation timed out
12/08/21 (19:56:12) | ERROR: <urlopen error timed out>
Traceback (most recent call last):
  File "/usr/local/Cellar/python@3.9/3.9.6/Frameworks/Python.framework/Versions/3.9/lib/python3.9/urllib/request.py", line 1346, in do_open
    h.request(req.get_method(), req.selector, req.data, headers,
  File "/usr/local/Cellar/python@3.9/3.9.6/Frameworks/Python.framework/Versions/3.9/lib/python3.9/http/client.py", line 1257, in request
    self._send_request(method, url, body, headers, encode_chunked)
  File "/usr/local/Cellar/python@3.9/3.9.6/Frameworks/Python.framework/Versions/3.9/lib/python3.9/http/client.py", line 1303, in _send_request
    self.endheaders(body, encode_chunked=encode_chunked)
  File "/usr/local/Cellar/python@3.9/3.9.6/Frameworks/Python.framework/Versions/3.9/lib/python3.9/http/client.py", line 1252, in endheaders
    self._send_output(message_body, encode_chunked=encode_chunked)
  File "/usr/local/Cellar/python@3.9/3.9.6/Frameworks/Python.framework/Versions/3.9/lib/python3.9/http/client.py", line 1012, in _send_output
    self.send(msg)
  File "/usr/local/Cellar/python@3.9/3.9.6/Frameworks/Python.framework/Versions/3.9/lib/python3.9/http/client.py", line 952, in send
    self.connect()
  File "/usr/local/Cellar/python@3.9/3.9.6/Frameworks/Python.framework/Versions/3.9/lib/python3.9/http/client.py", line 1419, in connect
    super().connect()
  File "/usr/local/Cellar/python@3.9/3.9.6/Frameworks/Python.framework/Versions/3.9/lib/python3.9/http/client.py", line 923, in connect
    self.sock = self._create_connection(
  File "/usr/local/Cellar/python@3.9/3.9.6/Frameworks/Python.framework/Versions/3.9/lib/python3.9/socket.py", line 843, in create_connection
    raise err
  File "/usr/local/Cellar/python@3.9/3.9.6/Frameworks/Python.framework/Versions/3.9/lib/python3.9/socket.py", line 831, in create_connection
    sock.connect(sa)
socket.timeout: timed out

During handling of the above exception, another exception occurred:

Traceback (most recent call last):
  File "/usr/local/bin/bpytop", line 5009, in _checker
    with urllib.request.urlopen("https://github.com/aristocratos/bpytop/raw/master/bpytop.py", timeout=5) as source: # type: ignore
  File "/usr/local/Cellar/python@3.9/3.9.6/Frameworks/Python.framework/Versions/3.9/lib/python3.9/urllib/request.py", line 214, in urlopen
    return opener.open(url, data, timeout)
  File "/usr/local/Cellar/python@3.9/3.9.6/Frameworks/Python.framework/Versions/3.9/lib/python3.9/urllib/request.py", line 517, in open
    response = self._open(req, data)
  File "/usr/local/Cellar/python@3.9/3.9.6/Frameworks/Python.framework/Versions/3.9/lib/python3.9/urllib/request.py", line 534, in _open
    result = self._call_chain(self.handle_open, protocol, protocol +
  File "/usr/local/Cellar/python@3.9/3.9.6/Frameworks/Python.framework/Versions/3.9/lib/python3.9/urllib/request.py", line 494, in _call_chain
    result = func(*args)
  File "/usr/local/Cellar/python@3.9/3.9.6/Frameworks/Python.framework/Versions/3.9/lib/python3.9/urllib/request.py", line 1389, in https_open
    return self.do_open(http.client.HTTPSConnection, req,
  File "/usr/local/Cellar/python@3.9/3.9.6/Frameworks/Python.framework/Versions/3.9/lib/python3.9/urllib/request.py", line 1349, in do_open
    raise URLError(err)
urllib.error.URLError: <urlopen error timed out>
12/08/21 (19:56:37) | ERROR: <urlopen error timed out>
Traceback (most recent call last):
  File "/usr/local/Cellar/python@3.9/3.9.6/Frameworks/Python.framework/Versions/3.9/lib/python3.9/urllib/request.py", line 1346, in do_open
    h.request(req.get_method(), req.selector, req.data, headers,
  File "/usr/local/Cellar/python@3.9/3.9.6/Frameworks/Python.framework/Versions/3.9/lib/python3.9/http/client.py", line 1257, in request
    self._send_request(method, url, body, headers, encode_chunked)
  File "/usr/local/Cellar/python@3.9/3.9.6/Frameworks/Python.framework/Versions/3.9/lib/python3.9/http/client.py", line 1303, in _send_request
    self.endheaders(body, encode_chunked=encode_chunked)
  File "/usr/local/Cellar/python@3.9/3.9.6/Frameworks/Python.framework/Versions/3.9/lib/python3.9/http/client.py", line 1252, in endheaders
    self._send_output(message_body, encode_chunked=encode_chunked)
  File "/usr/local/Cellar/python@3.9/3.9.6/Frameworks/Python.framework/Versions/3.9/lib/python3.9/http/client.py", line 1012, in _send_output
    self.send(msg)
  File "/usr/local/Cellar/python@3.9/3.9.6/Frameworks/Python.framework/Versions/3.9/lib/python3.9/http/client.py", line 952, in send
    self.connect()
  File "/usr/local/Cellar/python@3.9/3.9.6/Frameworks/Python.framework/Versions/3.9/lib/python3.9/http/client.py", line 1419, in connect
    super().connect()
  File "/usr/local/Cellar/python@3.9/3.9.6/Frameworks/Python.framework/Versions/3.9/lib/python3.9/http/client.py", line 923, in connect
    self.sock = self._create_connection(
  File "/usr/local/Cellar/python@3.9/3.9.6/Frameworks/Python.framework/Versions/3.9/lib/python3.9/socket.py", line 843, in create_connection
    raise err
  File "/usr/local/Cellar/python@3.9/3.9.6/Frameworks/Python.framework/Versions/3.9/lib/python3.9/socket.py", line 831, in create_connection
    sock.connect(sa)
socket.timeout: timed out

During handling of the above exception, another exception occurred:

Traceback (most recent call last):
  File "/usr/local/bin/bpytop", line 5009, in _checker
    with urllib.request.urlopen("https://github.com/aristocratos/bpytop/raw/master/bpytop.py", timeout=5) as source: # type: ignore
  File "/usr/local/Cellar/python@3.9/3.9.6/Frameworks/Python.framework/Versions/3.9/lib/python3.9/urllib/request.py", line 214, in urlopen
    return opener.open(url, data, timeout)
  File "/usr/local/Cellar/python@3.9/3.9.6/Frameworks/Python.framework/Versions/3.9/lib/python3.9/urllib/request.py", line 517, in open
    response = self._open(req, data)
  File "/usr/local/Cellar/python@3.9/3.9.6/Frameworks/Python.framework/Versions/3.9/lib/python3.9/urllib/request.py", line 534, in _open
    result = self._call_chain(self.handle_open, protocol, protocol +
  File "/usr/local/Cellar/python@3.9/3.9.6/Frameworks/Python.framework/Versions/3.9/lib/python3.9/urllib/request.py", line 494, in _call_chain
    result = func(*args)
  File "/usr/local/Cellar/python@3.9/3.9.6/Frameworks/Python.framework/Versions/3.9/lib/python3.9/urllib/request.py", line 1389, in https_open
    return self.do_open(http.client.HTTPSConnection, req,
  File "/usr/local/Cellar/python@3.9/3.9.6/Frameworks/Python.framework/Versions/3.9/lib/python3.9/urllib/request.py", line 1349, in do_open
    raise URLError(err)
urllib.error.URLError: <urlopen error timed out>
12/08/21 (19:57:15) | ERROR: The read operation timed out
Traceback (most recent call last):
  File "/usr/local/bin/bpytop", line 5009, in _checker
    with urllib.request.urlopen("https://github.com/aristocratos/bpytop/raw/master/bpytop.py", timeout=5) as source: # type: ignore
  File "/usr/local/Cellar/python@3.9/3.9.6/Frameworks/Python.framework/Versions/3.9/lib/python3.9/urllib/request.py", line 214, in urlopen
    return opener.open(url, data, timeout)
  File "/usr/local/Cellar/python@3.9/3.9.6/Frameworks/Python.framework/Versions/3.9/lib/python3.9/urllib/request.py", line 517, in open
    response = self._open(req, data)
  File "/usr/local/Cellar/python@3.9/3.9.6/Frameworks/Python.framework/Versions/3.9/lib/python3.9/urllib/request.py", line 534, in _open
    result = self._call_chain(self.handle_open, protocol, protocol +
  File "/usr/local/Cellar/python@3.9/3.9.6/Frameworks/Python.framework/Versions/3.9/lib/python3.9/urllib/request.py", line 494, in _call_chain
    result = func(*args)
  File "/usr/local/Cellar/python@3.9/3.9.6/Frameworks/Python.framework/Versions/3.9/lib/python3.9/urllib/request.py", line 1389, in https_open
    return self.do_open(http.client.HTTPSConnection, req,
  File "/usr/local/Cellar/python@3.9/3.9.6/Frameworks/Python.framework/Versions/3.9/lib/python3.9/urllib/request.py", line 1350, in do_open
    r = h.getresponse()
  File "/usr/local/Cellar/python@3.9/3.9.6/Frameworks/Python.framework/Versions/3.9/lib/python3.9/http/client.py", line 1349, in getresponse
    response.begin()
  File "/usr/local/Cellar/python@3.9/3.9.6/Frameworks/Python.framework/Versions/3.9/lib/python3.9/http/client.py", line 316, in begin
    version, status, reason = self._read_status()
  File "/usr/local/Cellar/python@3.9/3.9.6/Frameworks/Python.framework/Versions/3.9/lib/python3.9/http/client.py", line 277, in _read_status
    line = str(self.fp.readline(_MAXLINE + 1), "iso-8859-1")
  File "/usr/local/Cellar/python@3.9/3.9.6/Frameworks/Python.framework/Versions/3.9/lib/python3.9/socket.py", line 704, in readinto
    return self._sock.recv_into(b)
  File "/usr/local/Cellar/python@3.9/3.9.6/Frameworks/Python.framework/Versions/3.9/lib/python3.9/ssl.py", line 1241, in recv_into
    return self.read(nbytes, buffer)
  File "/usr/local/Cellar/python@3.9/3.9.6/Frameworks/Python.framework/Versions/3.9/lib/python3.9/ssl.py", line 1099, in read
    return self._sslobj.read(len, buffer)
socket.timeout: The read operation timed out
07/09/21 (14:05:45) | ERROR: The read operation timed out
Traceback (most recent call last):
  File "/usr/local/bin/bpytop", line 5009, in _checker
    with urllib.request.urlopen("https://github.com/aristocratos/bpytop/raw/master/bpytop.py", timeout=5) as source: # type: ignore
  File "/usr/local/Cellar/python@3.9/3.9.7/Frameworks/Python.framework/Versions/3.9/lib/python3.9/urllib/request.py", line 214, in urlopen
    return opener.open(url, data, timeout)
  File "/usr/local/Cellar/python@3.9/3.9.7/Frameworks/Python.framework/Versions/3.9/lib/python3.9/urllib/request.py", line 523, in open
    response = meth(req, response)
  File "/usr/local/Cellar/python@3.9/3.9.7/Frameworks/Python.framework/Versions/3.9/lib/python3.9/urllib/request.py", line 632, in http_response
    response = self.parent.error(
  File "/usr/local/Cellar/python@3.9/3.9.7/Frameworks/Python.framework/Versions/3.9/lib/python3.9/urllib/request.py", line 555, in error
    result = self._call_chain(*args)
  File "/usr/local/Cellar/python@3.9/3.9.7/Frameworks/Python.framework/Versions/3.9/lib/python3.9/urllib/request.py", line 494, in _call_chain
    result = func(*args)
  File "/usr/local/Cellar/python@3.9/3.9.7/Frameworks/Python.framework/Versions/3.9/lib/python3.9/urllib/request.py", line 747, in http_error_302
    return self.parent.open(new, timeout=req.timeout)
  File "/usr/local/Cellar/python@3.9/3.9.7/Frameworks/Python.framework/Versions/3.9/lib/python3.9/urllib/request.py", line 517, in open
    response = self._open(req, data)
  File "/usr/local/Cellar/python@3.9/3.9.7/Frameworks/Python.framework/Versions/3.9/lib/python3.9/urllib/request.py", line 534, in _open
    result = self._call_chain(self.handle_open, protocol, protocol +
  File "/usr/local/Cellar/python@3.9/3.9.7/Frameworks/Python.framework/Versions/3.9/lib/python3.9/urllib/request.py", line 494, in _call_chain
    result = func(*args)
  File "/usr/local/Cellar/python@3.9/3.9.7/Frameworks/Python.framework/Versions/3.9/lib/python3.9/urllib/request.py", line 1389, in https_open
    return self.do_open(http.client.HTTPSConnection, req,
  File "/usr/local/Cellar/python@3.9/3.9.7/Frameworks/Python.framework/Versions/3.9/lib/python3.9/urllib/request.py", line 1350, in do_open
    r = h.getresponse()
  File "/usr/local/Cellar/python@3.9/3.9.7/Frameworks/Python.framework/Versions/3.9/lib/python3.9/http/client.py", line 1371, in getresponse
    response.begin()
  File "/usr/local/Cellar/python@3.9/3.9.7/Frameworks/Python.framework/Versions/3.9/lib/python3.9/http/client.py", line 319, in begin
    version, status, reason = self._read_status()
  File "/usr/local/Cellar/python@3.9/3.9.7/Frameworks/Python.framework/Versions/3.9/lib/python3.9/http/client.py", line 280, in _read_status
    line = str(self.fp.readline(_MAXLINE + 1), "iso-8859-1")
  File "/usr/local/Cellar/python@3.9/3.9.7/Frameworks/Python.framework/Versions/3.9/lib/python3.9/socket.py", line 704, in readinto
    return self._sock.recv_into(b)
  File "/usr/local/Cellar/python@3.9/3.9.7/Frameworks/Python.framework/Versions/3.9/lib/python3.9/ssl.py", line 1241, in recv_into
    return self.read(nbytes, buffer)
  File "/usr/local/Cellar/python@3.9/3.9.7/Frameworks/Python.framework/Versions/3.9/lib/python3.9/ssl.py", line 1099, in read
    return self._sslobj.read(len, buffer)
socket.timeout: The read operation timed out
09/09/21 (17:33:50) | ERROR: The read operation timed out
Traceback (most recent call last):
  File "/usr/local/bin/bpytop", line 5009, in _checker
    with urllib.request.urlopen("https://github.com/aristocratos/bpytop/raw/master/bpytop.py", timeout=5) as source: # type: ignore
  File "/usr/local/Cellar/python@3.9/3.9.7/Frameworks/Python.framework/Versions/3.9/lib/python3.9/urllib/request.py", line 214, in urlopen
    return opener.open(url, data, timeout)
  File "/usr/local/Cellar/python@3.9/3.9.7/Frameworks/Python.framework/Versions/3.9/lib/python3.9/urllib/request.py", line 523, in open
    response = meth(req, response)
  File "/usr/local/Cellar/python@3.9/3.9.7/Frameworks/Python.framework/Versions/3.9/lib/python3.9/urllib/request.py", line 632, in http_response
    response = self.parent.error(
  File "/usr/local/Cellar/python@3.9/3.9.7/Frameworks/Python.framework/Versions/3.9/lib/python3.9/urllib/request.py", line 555, in error
    result = self._call_chain(*args)
  File "/usr/local/Cellar/python@3.9/3.9.7/Frameworks/Python.framework/Versions/3.9/lib/python3.9/urllib/request.py", line 494, in _call_chain
    result = func(*args)
  File "/usr/local/Cellar/python@3.9/3.9.7/Frameworks/Python.framework/Versions/3.9/lib/python3.9/urllib/request.py", line 747, in http_error_302
    return self.parent.open(new, timeout=req.timeout)
  File "/usr/local/Cellar/python@3.9/3.9.7/Frameworks/Python.framework/Versions/3.9/lib/python3.9/urllib/request.py", line 517, in open
    response = self._open(req, data)
  File "/usr/local/Cellar/python@3.9/3.9.7/Frameworks/Python.framework/Versions/3.9/lib/python3.9/urllib/request.py", line 534, in _open
    result = self._call_chain(self.handle_open, protocol, protocol +
  File "/usr/local/Cellar/python@3.9/3.9.7/Frameworks/Python.framework/Versions/3.9/lib/python3.9/urllib/request.py", line 494, in _call_chain
    result = func(*args)
  File "/usr/local/Cellar/python@3.9/3.9.7/Frameworks/Python.framework/Versions/3.9/lib/python3.9/urllib/request.py", line 1389, in https_open
    return self.do_open(http.client.HTTPSConnection, req,
  File "/usr/local/Cellar/python@3.9/3.9.7/Frameworks/Python.framework/Versions/3.9/lib/python3.9/urllib/request.py", line 1350, in do_open
    r = h.getresponse()
  File "/usr/local/Cellar/python@3.9/3.9.7/Frameworks/Python.framework/Versions/3.9/lib/python3.9/http/client.py", line 1371, in getresponse
    response.begin()
  File "/usr/local/Cellar/python@3.9/3.9.7/Frameworks/Python.framework/Versions/3.9/lib/python3.9/http/client.py", line 319, in begin
    version, status, reason = self._read_status()
  File "/usr/local/Cellar/python@3.9/3.9.7/Frameworks/Python.framework/Versions/3.9/lib/python3.9/http/client.py", line 280, in _read_status
    line = str(self.fp.readline(_MAXLINE + 1), "iso-8859-1")
  File "/usr/local/Cellar/python@3.9/3.9.7/Frameworks/Python.framework/Versions/3.9/lib/python3.9/socket.py", line 704, in readinto
    return self._sock.recv_into(b)
  File "/usr/local/Cellar/python@3.9/3.9.7/Frameworks/Python.framework/Versions/3.9/lib/python3.9/ssl.py", line 1241, in recv_into
    return self.read(nbytes, buffer)
  File "/usr/local/Cellar/python@3.9/3.9.7/Frameworks/Python.framework/Versions/3.9/lib/python3.9/ssl.py", line 1099, in read
    return self._sslobj.read(len, buffer)
socket.timeout: The read operation timed out
09/09/21 (17:35:19) | ERROR: The read operation timed out
Traceback (most recent call last):
  File "/usr/local/bin/bpytop", line 5009, in _checker
    with urllib.request.urlopen("https://github.com/aristocratos/bpytop/raw/master/bpytop.py", timeout=5) as source: # type: ignore
  File "/usr/local/Cellar/python@3.9/3.9.7/Frameworks/Python.framework/Versions/3.9/lib/python3.9/urllib/request.py", line 214, in urlopen
    return opener.open(url, data, timeout)
  File "/usr/local/Cellar/python@3.9/3.9.7/Frameworks/Python.framework/Versions/3.9/lib/python3.9/urllib/request.py", line 517, in open
    response = self._open(req, data)
  File "/usr/local/Cellar/python@3.9/3.9.7/Frameworks/Python.framework/Versions/3.9/lib/python3.9/urllib/request.py", line 534, in _open
    result = self._call_chain(self.handle_open, protocol, protocol +
  File "/usr/local/Cellar/python@3.9/3.9.7/Frameworks/Python.framework/Versions/3.9/lib/python3.9/urllib/request.py", line 494, in _call_chain
    result = func(*args)
  File "/usr/local/Cellar/python@3.9/3.9.7/Frameworks/Python.framework/Versions/3.9/lib/python3.9/urllib/request.py", line 1389, in https_open
    return self.do_open(http.client.HTTPSConnection, req,
  File "/usr/local/Cellar/python@3.9/3.9.7/Frameworks/Python.framework/Versions/3.9/lib/python3.9/urllib/request.py", line 1350, in do_open
    r = h.getresponse()
  File "/usr/local/Cellar/python@3.9/3.9.7/Frameworks/Python.framework/Versions/3.9/lib/python3.9/http/client.py", line 1371, in getresponse
    response.begin()
  File "/usr/local/Cellar/python@3.9/3.9.7/Frameworks/Python.framework/Versions/3.9/lib/python3.9/http/client.py", line 319, in begin
    version, status, reason = self._read_status()
  File "/usr/local/Cellar/python@3.9/3.9.7/Frameworks/Python.framework/Versions/3.9/lib/python3.9/http/client.py", line 280, in _read_status
    line = str(self.fp.readline(_MAXLINE + 1), "iso-8859-1")
  File "/usr/local/Cellar/python@3.9/3.9.7/Frameworks/Python.framework/Versions/3.9/lib/python3.9/socket.py", line 704, in readinto
    return self._sock.recv_into(b)
  File "/usr/local/Cellar/python@3.9/3.9.7/Frameworks/Python.framework/Versions/3.9/lib/python3.9/ssl.py", line 1241, in recv_into
    return self.read(nbytes, buffer)
  File "/usr/local/Cellar/python@3.9/3.9.7/Frameworks/Python.framework/Versions/3.9/lib/python3.9/ssl.py", line 1099, in read
    return self._sslobj.read(len, buffer)
socket.timeout: The read operation timed out
14/09/21 (21:06:09) | ERROR: <urlopen error timed out>
Traceback (most recent call last):
  File "/usr/local/Cellar/python@3.9/3.9.7/Frameworks/Python.framework/Versions/3.9/lib/python3.9/urllib/request.py", line 1346, in do_open
    h.request(req.get_method(), req.selector, req.data, headers,
  File "/usr/local/Cellar/python@3.9/3.9.7/Frameworks/Python.framework/Versions/3.9/lib/python3.9/http/client.py", line 1279, in request
    self._send_request(method, url, body, headers, encode_chunked)
  File "/usr/local/Cellar/python@3.9/3.9.7/Frameworks/Python.framework/Versions/3.9/lib/python3.9/http/client.py", line 1325, in _send_request
    self.endheaders(body, encode_chunked=encode_chunked)
  File "/usr/local/Cellar/python@3.9/3.9.7/Frameworks/Python.framework/Versions/3.9/lib/python3.9/http/client.py", line 1274, in endheaders
    self._send_output(message_body, encode_chunked=encode_chunked)
  File "/usr/local/Cellar/python@3.9/3.9.7/Frameworks/Python.framework/Versions/3.9/lib/python3.9/http/client.py", line 1034, in _send_output
    self.send(msg)
  File "/usr/local/Cellar/python@3.9/3.9.7/Frameworks/Python.framework/Versions/3.9/lib/python3.9/http/client.py", line 974, in send
    self.connect()
  File "/usr/local/Cellar/python@3.9/3.9.7/Frameworks/Python.framework/Versions/3.9/lib/python3.9/http/client.py", line 1441, in connect
    super().connect()
  File "/usr/local/Cellar/python@3.9/3.9.7/Frameworks/Python.framework/Versions/3.9/lib/python3.9/http/client.py", line 945, in connect
    self.sock = self._create_connection(
  File "/usr/local/Cellar/python@3.9/3.9.7/Frameworks/Python.framework/Versions/3.9/lib/python3.9/socket.py", line 844, in create_connection
    raise err
  File "/usr/local/Cellar/python@3.9/3.9.7/Frameworks/Python.framework/Versions/3.9/lib/python3.9/socket.py", line 832, in create_connection
    sock.connect(sa)
socket.timeout: timed out

During handling of the above exception, another exception occurred:

Traceback (most recent call last):
  File "/usr/local/bin/bpytop", line 5009, in _checker
    with urllib.request.urlopen("https://github.com/aristocratos/bpytop/raw/master/bpytop.py", timeout=5) as source: # type: ignore
  File "/usr/local/Cellar/python@3.9/3.9.7/Frameworks/Python.framework/Versions/3.9/lib/python3.9/urllib/request.py", line 214, in urlopen
    return opener.open(url, data, timeout)
  File "/usr/local/Cellar/python@3.9/3.9.7/Frameworks/Python.framework/Versions/3.9/lib/python3.9/urllib/request.py", line 517, in open
    response = self._open(req, data)
  File "/usr/local/Cellar/python@3.9/3.9.7/Frameworks/Python.framework/Versions/3.9/lib/python3.9/urllib/request.py", line 534, in _open
    result = self._call_chain(self.handle_open, protocol, protocol +
  File "/usr/local/Cellar/python@3.9/3.9.7/Frameworks/Python.framework/Versions/3.9/lib/python3.9/urllib/request.py", line 494, in _call_chain
    result = func(*args)
  File "/usr/local/Cellar/python@3.9/3.9.7/Frameworks/Python.framework/Versions/3.9/lib/python3.9/urllib/request.py", line 1389, in https_open
    return self.do_open(http.client.HTTPSConnection, req,
  File "/usr/local/Cellar/python@3.9/3.9.7/Frameworks/Python.framework/Versions/3.9/lib/python3.9/urllib/request.py", line 1349, in do_open
    raise URLError(err)
urllib.error.URLError: <urlopen error timed out>
08/10/21 (22:48:18) | ERROR: <urlopen error timed out>
Traceback (most recent call last):
  File "/usr/local/Cellar/python@3.10/3.10.0_1/Frameworks/Python.framework/Versions/3.10/lib/python3.10/urllib/request.py", line 1348, in do_open
    h.request(req.get_method(), req.selector, req.data, headers,
  File "/usr/local/Cellar/python@3.10/3.10.0_1/Frameworks/Python.framework/Versions/3.10/lib/python3.10/http/client.py", line 1276, in request
    self._send_request(method, url, body, headers, encode_chunked)
  File "/usr/local/Cellar/python@3.10/3.10.0_1/Frameworks/Python.framework/Versions/3.10/lib/python3.10/http/client.py", line 1322, in _send_request
    self.endheaders(body, encode_chunked=encode_chunked)
  File "/usr/local/Cellar/python@3.10/3.10.0_1/Frameworks/Python.framework/Versions/3.10/lib/python3.10/http/client.py", line 1271, in endheaders
    self._send_output(message_body, encode_chunked=encode_chunked)
  File "/usr/local/Cellar/python@3.10/3.10.0_1/Frameworks/Python.framework/Versions/3.10/lib/python3.10/http/client.py", line 1031, in _send_output
    self.send(msg)
  File "/usr/local/Cellar/python@3.10/3.10.0_1/Frameworks/Python.framework/Versions/3.10/lib/python3.10/http/client.py", line 969, in send
    self.connect()
  File "/usr/local/Cellar/python@3.10/3.10.0_1/Frameworks/Python.framework/Versions/3.10/lib/python3.10/http/client.py", line 1441, in connect
    super().connect()
  File "/usr/local/Cellar/python@3.10/3.10.0_1/Frameworks/Python.framework/Versions/3.10/lib/python3.10/http/client.py", line 940, in connect
    self.sock = self._create_connection(
  File "/usr/local/Cellar/python@3.10/3.10.0_1/Frameworks/Python.framework/Versions/3.10/lib/python3.10/socket.py", line 845, in create_connection
    raise err
  File "/usr/local/Cellar/python@3.10/3.10.0_1/Frameworks/Python.framework/Versions/3.10/lib/python3.10/socket.py", line 833, in create_connection
    sock.connect(sa)
TimeoutError: timed out

During handling of the above exception, another exception occurred:

Traceback (most recent call last):
  File "/usr/local/bin/bpytop", line 5009, in _checker
    with urllib.request.urlopen("https://github.com/aristocratos/bpytop/raw/master/bpytop.py", timeout=5) as source: # type: ignore
  File "/usr/local/Cellar/python@3.10/3.10.0_1/Frameworks/Python.framework/Versions/3.10/lib/python3.10/urllib/request.py", line 216, in urlopen
    return opener.open(url, data, timeout)
  File "/usr/local/Cellar/python@3.10/3.10.0_1/Frameworks/Python.framework/Versions/3.10/lib/python3.10/urllib/request.py", line 519, in open
    response = self._open(req, data)
  File "/usr/local/Cellar/python@3.10/3.10.0_1/Frameworks/Python.framework/Versions/3.10/lib/python3.10/urllib/request.py", line 536, in _open
    result = self._call_chain(self.handle_open, protocol, protocol +
  File "/usr/local/Cellar/python@3.10/3.10.0_1/Frameworks/Python.framework/Versions/3.10/lib/python3.10/urllib/request.py", line 496, in _call_chain
    result = func(*args)
  File "/usr/local/Cellar/python@3.10/3.10.0_1/Frameworks/Python.framework/Versions/3.10/lib/python3.10/urllib/request.py", line 1391, in https_open
    return self.do_open(http.client.HTTPSConnection, req,
  File "/usr/local/Cellar/python@3.10/3.10.0_1/Frameworks/Python.framework/Versions/3.10/lib/python3.10/urllib/request.py", line 1351, in do_open
    raise URLError(err)
urllib.error.URLError: <urlopen error timed out>
14/10/21 (06:09:16) | ERROR: The read operation timed out
Traceback (most recent call last):
  File "/usr/local/bin/bpytop", line 5009, in _checker
    with urllib.request.urlopen("https://github.com/aristocratos/bpytop/raw/master/bpytop.py", timeout=5) as source: # type: ignore
  File "/usr/local/Cellar/python@3.10/3.10.0_2/Frameworks/Python.framework/Versions/3.10/lib/python3.10/urllib/request.py", line 216, in urlopen
    return opener.open(url, data, timeout)
  File "/usr/local/Cellar/python@3.10/3.10.0_2/Frameworks/Python.framework/Versions/3.10/lib/python3.10/urllib/request.py", line 519, in open
    response = self._open(req, data)
  File "/usr/local/Cellar/python@3.10/3.10.0_2/Frameworks/Python.framework/Versions/3.10/lib/python3.10/urllib/request.py", line 536, in _open
    result = self._call_chain(self.handle_open, protocol, protocol +
  File "/usr/local/Cellar/python@3.10/3.10.0_2/Frameworks/Python.framework/Versions/3.10/lib/python3.10/urllib/request.py", line 496, in _call_chain
    result = func(*args)
  File "/usr/local/Cellar/python@3.10/3.10.0_2/Frameworks/Python.framework/Versions/3.10/lib/python3.10/urllib/request.py", line 1391, in https_open
    return self.do_open(http.client.HTTPSConnection, req,
  File "/usr/local/Cellar/python@3.10/3.10.0_2/Frameworks/Python.framework/Versions/3.10/lib/python3.10/urllib/request.py", line 1352, in do_open
    r = h.getresponse()
  File "/usr/local/Cellar/python@3.10/3.10.0_2/Frameworks/Python.framework/Versions/3.10/lib/python3.10/http/client.py", line 1368, in getresponse
    response.begin()
  File "/usr/local/Cellar/python@3.10/3.10.0_2/Frameworks/Python.framework/Versions/3.10/lib/python3.10/http/client.py", line 317, in begin
    version, status, reason = self._read_status()
  File "/usr/local/Cellar/python@3.10/3.10.0_2/Frameworks/Python.framework/Versions/3.10/lib/python3.10/http/client.py", line 278, in _read_status
    line = str(self.fp.readline(_MAXLINE + 1), "iso-8859-1")
  File "/usr/local/Cellar/python@3.10/3.10.0_2/Frameworks/Python.framework/Versions/3.10/lib/python3.10/socket.py", line 705, in readinto
    return self._sock.recv_into(b)
  File "/usr/local/Cellar/python@3.10/3.10.0_2/Frameworks/Python.framework/Versions/3.10/lib/python3.10/ssl.py", line 1273, in recv_into
    return self.read(nbytes, buffer)
  File "/usr/local/Cellar/python@3.10/3.10.0_2/Frameworks/Python.framework/Versions/3.10/lib/python3.10/ssl.py", line 1129, in read
    return self._sslobj.read(len, buffer)
TimeoutError: The read operation timed out
14/10/21 (06:31:03) | ERROR: The read operation timed out
Traceback (most recent call last):
  File "/usr/local/bin/bpytop", line 5009, in _checker
    with urllib.request.urlopen("https://github.com/aristocratos/bpytop/raw/master/bpytop.py", timeout=5) as source: # type: ignore
  File "/usr/local/Cellar/python@3.10/3.10.0_2/Frameworks/Python.framework/Versions/3.10/lib/python3.10/urllib/request.py", line 216, in urlopen
    return opener.open(url, data, timeout)
  File "/usr/local/Cellar/python@3.10/3.10.0_2/Frameworks/Python.framework/Versions/3.10/lib/python3.10/urllib/request.py", line 519, in open
    response = self._open(req, data)
  File "/usr/local/Cellar/python@3.10/3.10.0_2/Frameworks/Python.framework/Versions/3.10/lib/python3.10/urllib/request.py", line 536, in _open
    result = self._call_chain(self.handle_open, protocol, protocol +
  File "/usr/local/Cellar/python@3.10/3.10.0_2/Frameworks/Python.framework/Versions/3.10/lib/python3.10/urllib/request.py", line 496, in _call_chain
    result = func(*args)
  File "/usr/local/Cellar/python@3.10/3.10.0_2/Frameworks/Python.framework/Versions/3.10/lib/python3.10/urllib/request.py", line 1391, in https_open
    return self.do_open(http.client.HTTPSConnection, req,
  File "/usr/local/Cellar/python@3.10/3.10.0_2/Frameworks/Python.framework/Versions/3.10/lib/python3.10/urllib/request.py", line 1352, in do_open
    r = h.getresponse()
  File "/usr/local/Cellar/python@3.10/3.10.0_2/Frameworks/Python.framework/Versions/3.10/lib/python3.10/http/client.py", line 1368, in getresponse
    response.begin()
  File "/usr/local/Cellar/python@3.10/3.10.0_2/Frameworks/Python.framework/Versions/3.10/lib/python3.10/http/client.py", line 317, in begin
    version, status, reason = self._read_status()
  File "/usr/local/Cellar/python@3.10/3.10.0_2/Frameworks/Python.framework/Versions/3.10/lib/python3.10/http/client.py", line 278, in _read_status
    line = str(self.fp.readline(_MAXLINE + 1), "iso-8859-1")
  File "/usr/local/Cellar/python@3.10/3.10.0_2/Frameworks/Python.framework/Versions/3.10/lib/python3.10/socket.py", line 705, in readinto
    return self._sock.recv_into(b)
  File "/usr/local/Cellar/python@3.10/3.10.0_2/Frameworks/Python.framework/Versions/3.10/lib/python3.10/ssl.py", line 1273, in recv_into
    return self.read(nbytes, buffer)
  File "/usr/local/Cellar/python@3.10/3.10.0_2/Frameworks/Python.framework/Versions/3.10/lib/python3.10/ssl.py", line 1129, in read
    return self._sslobj.read(len, buffer)
TimeoutError: The read operation timed out
14/10/21 (06:51:52) | ERROR: The read operation timed out
Traceback (most recent call last):
  File "/usr/local/bin/bpytop", line 5009, in _checker
    with urllib.request.urlopen("https://github.com/aristocratos/bpytop/raw/master/bpytop.py", timeout=5) as source: # type: ignore
  File "/usr/local/Cellar/python@3.10/3.10.0_2/Frameworks/Python.framework/Versions/3.10/lib/python3.10/urllib/request.py", line 216, in urlopen
    return opener.open(url, data, timeout)
  File "/usr/local/Cellar/python@3.10/3.10.0_2/Frameworks/Python.framework/Versions/3.10/lib/python3.10/urllib/request.py", line 519, in open
    response = self._open(req, data)
  File "/usr/local/Cellar/python@3.10/3.10.0_2/Frameworks/Python.framework/Versions/3.10/lib/python3.10/urllib/request.py", line 536, in _open
    result = self._call_chain(self.handle_open, protocol, protocol +
  File "/usr/local/Cellar/python@3.10/3.10.0_2/Frameworks/Python.framework/Versions/3.10/lib/python3.10/urllib/request.py", line 496, in _call_chain
    result = func(*args)
  File "/usr/local/Cellar/python@3.10/3.10.0_2/Frameworks/Python.framework/Versions/3.10/lib/python3.10/urllib/request.py", line 1391, in https_open
    return self.do_open(http.client.HTTPSConnection, req,
  File "/usr/local/Cellar/python@3.10/3.10.0_2/Frameworks/Python.framework/Versions/3.10/lib/python3.10/urllib/request.py", line 1352, in do_open
    r = h.getresponse()
  File "/usr/local/Cellar/python@3.10/3.10.0_2/Frameworks/Python.framework/Versions/3.10/lib/python3.10/http/client.py", line 1368, in getresponse
    response.begin()
  File "/usr/local/Cellar/python@3.10/3.10.0_2/Frameworks/Python.framework/Versions/3.10/lib/python3.10/http/client.py", line 317, in begin
    version, status, reason = self._read_status()
  File "/usr/local/Cellar/python@3.10/3.10.0_2/Frameworks/Python.framework/Versions/3.10/lib/python3.10/http/client.py", line 278, in _read_status
    line = str(self.fp.readline(_MAXLINE + 1), "iso-8859-1")
  File "/usr/local/Cellar/python@3.10/3.10.0_2/Frameworks/Python.framework/Versions/3.10/lib/python3.10/socket.py", line 705, in readinto
    return self._sock.recv_into(b)
  File "/usr/local/Cellar/python@3.10/3.10.0_2/Frameworks/Python.framework/Versions/3.10/lib/python3.10/ssl.py", line 1273, in recv_into
    return self.read(nbytes, buffer)
  File "/usr/local/Cellar/python@3.10/3.10.0_2/Frameworks/Python.framework/Versions/3.10/lib/python3.10/ssl.py", line 1129, in read
    return self._sslobj.read(len, buffer)
TimeoutError: The read operation timed out
14/10/21 (07:42:53) | ERROR: The read operation timed out
Traceback (most recent call last):
  File "/usr/local/bin/bpytop", line 5009, in _checker
    with urllib.request.urlopen("https://github.com/aristocratos/bpytop/raw/master/bpytop.py", timeout=5) as source: # type: ignore
  File "/usr/local/Cellar/python@3.10/3.10.0_2/Frameworks/Python.framework/Versions/3.10/lib/python3.10/urllib/request.py", line 216, in urlopen
    return opener.open(url, data, timeout)
  File "/usr/local/Cellar/python@3.10/3.10.0_2/Frameworks/Python.framework/Versions/3.10/lib/python3.10/urllib/request.py", line 525, in open
    response = meth(req, response)
  File "/usr/local/Cellar/python@3.10/3.10.0_2/Frameworks/Python.framework/Versions/3.10/lib/python3.10/urllib/request.py", line 634, in http_response
    response = self.parent.error(
  File "/usr/local/Cellar/python@3.10/3.10.0_2/Frameworks/Python.framework/Versions/3.10/lib/python3.10/urllib/request.py", line 557, in error
    result = self._call_chain(*args)
  File "/usr/local/Cellar/python@3.10/3.10.0_2/Frameworks/Python.framework/Versions/3.10/lib/python3.10/urllib/request.py", line 496, in _call_chain
    result = func(*args)
  File "/usr/local/Cellar/python@3.10/3.10.0_2/Frameworks/Python.framework/Versions/3.10/lib/python3.10/urllib/request.py", line 749, in http_error_302
    return self.parent.open(new, timeout=req.timeout)
  File "/usr/local/Cellar/python@3.10/3.10.0_2/Frameworks/Python.framework/Versions/3.10/lib/python3.10/urllib/request.py", line 519, in open
    response = self._open(req, data)
  File "/usr/local/Cellar/python@3.10/3.10.0_2/Frameworks/Python.framework/Versions/3.10/lib/python3.10/urllib/request.py", line 536, in _open
    result = self._call_chain(self.handle_open, protocol, protocol +
  File "/usr/local/Cellar/python@3.10/3.10.0_2/Frameworks/Python.framework/Versions/3.10/lib/python3.10/urllib/request.py", line 496, in _call_chain
    result = func(*args)
  File "/usr/local/Cellar/python@3.10/3.10.0_2/Frameworks/Python.framework/Versions/3.10/lib/python3.10/urllib/request.py", line 1391, in https_open
    return self.do_open(http.client.HTTPSConnection, req,
  File "/usr/local/Cellar/python@3.10/3.10.0_2/Frameworks/Python.framework/Versions/3.10/lib/python3.10/urllib/request.py", line 1352, in do_open
    r = h.getresponse()
  File "/usr/local/Cellar/python@3.10/3.10.0_2/Frameworks/Python.framework/Versions/3.10/lib/python3.10/http/client.py", line 1368, in getresponse
    response.begin()
  File "/usr/local/Cellar/python@3.10/3.10.0_2/Frameworks/Python.framework/Versions/3.10/lib/python3.10/http/client.py", line 317, in begin
    version, status, reason = self._read_status()
  File "/usr/local/Cellar/python@3.10/3.10.0_2/Frameworks/Python.framework/Versions/3.10/lib/python3.10/http/client.py", line 278, in _read_status
    line = str(self.fp.readline(_MAXLINE + 1), "iso-8859-1")
  File "/usr/local/Cellar/python@3.10/3.10.0_2/Frameworks/Python.framework/Versions/3.10/lib/python3.10/socket.py", line 705, in readinto
    return self._sock.recv_into(b)
  File "/usr/local/Cellar/python@3.10/3.10.0_2/Frameworks/Python.framework/Versions/3.10/lib/python3.10/ssl.py", line 1273, in recv_into
    return self.read(nbytes, buffer)
  File "/usr/local/Cellar/python@3.10/3.10.0_2/Frameworks/Python.framework/Versions/3.10/lib/python3.10/ssl.py", line 1129, in read
    return self._sslobj.read(len, buffer)
TimeoutError: The read operation timed out
20/10/21 (18:38:14) | ERROR: The read operation timed out
Traceback (most recent call last):
  File "/usr/local/bin/bpytop", line 5009, in _checker
    with urllib.request.urlopen("https://github.com/aristocratos/bpytop/raw/master/bpytop.py", timeout=5) as source: # type: ignore
  File "/usr/local/Cellar/python@3.10/3.10.0_2/Frameworks/Python.framework/Versions/3.10/lib/python3.10/urllib/request.py", line 216, in urlopen
    return opener.open(url, data, timeout)
  File "/usr/local/Cellar/python@3.10/3.10.0_2/Frameworks/Python.framework/Versions/3.10/lib/python3.10/urllib/request.py", line 519, in open
    response = self._open(req, data)
  File "/usr/local/Cellar/python@3.10/3.10.0_2/Frameworks/Python.framework/Versions/3.10/lib/python3.10/urllib/request.py", line 536, in _open
    result = self._call_chain(self.handle_open, protocol, protocol +
  File "/usr/local/Cellar/python@3.10/3.10.0_2/Frameworks/Python.framework/Versions/3.10/lib/python3.10/urllib/request.py", line 496, in _call_chain
    result = func(*args)
  File "/usr/local/Cellar/python@3.10/3.10.0_2/Frameworks/Python.framework/Versions/3.10/lib/python3.10/urllib/request.py", line 1391, in https_open
    return self.do_open(http.client.HTTPSConnection, req,
  File "/usr/local/Cellar/python@3.10/3.10.0_2/Frameworks/Python.framework/Versions/3.10/lib/python3.10/urllib/request.py", line 1352, in do_open
    r = h.getresponse()
  File "/usr/local/Cellar/python@3.10/3.10.0_2/Frameworks/Python.framework/Versions/3.10/lib/python3.10/http/client.py", line 1368, in getresponse
    response.begin()
  File "/usr/local/Cellar/python@3.10/3.10.0_2/Frameworks/Python.framework/Versions/3.10/lib/python3.10/http/client.py", line 317, in begin
    version, status, reason = self._read_status()
  File "/usr/local/Cellar/python@3.10/3.10.0_2/Frameworks/Python.framework/Versions/3.10/lib/python3.10/http/client.py", line 278, in _read_status
    line = str(self.fp.readline(_MAXLINE + 1), "iso-8859-1")
  File "/usr/local/Cellar/python@3.10/3.10.0_2/Frameworks/Python.framework/Versions/3.10/lib/python3.10/socket.py", line 705, in readinto
    return self._sock.recv_into(b)
  File "/usr/local/Cellar/python@3.10/3.10.0_2/Frameworks/Python.framework/Versions/3.10/lib/python3.10/ssl.py", line 1273, in recv_into
    return self.read(nbytes, buffer)
  File "/usr/local/Cellar/python@3.10/3.10.0_2/Frameworks/Python.framework/Versions/3.10/lib/python3.10/ssl.py", line 1129, in read
    return self._sslobj.read(len, buffer)
TimeoutError: The read operation timed out
20/10/21 (19:01:40) | ERROR: The read operation timed out
Traceback (most recent call last):
  File "/usr/local/bin/bpytop", line 5009, in _checker
    with urllib.request.urlopen("https://github.com/aristocratos/bpytop/raw/master/bpytop.py", timeout=5) as source: # type: ignore
  File "/usr/local/Cellar/python@3.10/3.10.0_2/Frameworks/Python.framework/Versions/3.10/lib/python3.10/urllib/request.py", line 216, in urlopen
    return opener.open(url, data, timeout)
  File "/usr/local/Cellar/python@3.10/3.10.0_2/Frameworks/Python.framework/Versions/3.10/lib/python3.10/urllib/request.py", line 519, in open
    response = self._open(req, data)
  File "/usr/local/Cellar/python@3.10/3.10.0_2/Frameworks/Python.framework/Versions/3.10/lib/python3.10/urllib/request.py", line 536, in _open
    result = self._call_chain(self.handle_open, protocol, protocol +
  File "/usr/local/Cellar/python@3.10/3.10.0_2/Frameworks/Python.framework/Versions/3.10/lib/python3.10/urllib/request.py", line 496, in _call_chain
    result = func(*args)
  File "/usr/local/Cellar/python@3.10/3.10.0_2/Frameworks/Python.framework/Versions/3.10/lib/python3.10/urllib/request.py", line 1391, in https_open
    return self.do_open(http.client.HTTPSConnection, req,
  File "/usr/local/Cellar/python@3.10/3.10.0_2/Frameworks/Python.framework/Versions/3.10/lib/python3.10/urllib/request.py", line 1352, in do_open
    r = h.getresponse()
  File "/usr/local/Cellar/python@3.10/3.10.0_2/Frameworks/Python.framework/Versions/3.10/lib/python3.10/http/client.py", line 1368, in getresponse
    response.begin()
  File "/usr/local/Cellar/python@3.10/3.10.0_2/Frameworks/Python.framework/Versions/3.10/lib/python3.10/http/client.py", line 317, in begin
    version, status, reason = self._read_status()
  File "/usr/local/Cellar/python@3.10/3.10.0_2/Frameworks/Python.framework/Versions/3.10/lib/python3.10/http/client.py", line 278, in _read_status
    line = str(self.fp.readline(_MAXLINE + 1), "iso-8859-1")
  File "/usr/local/Cellar/python@3.10/3.10.0_2/Frameworks/Python.framework/Versions/3.10/lib/python3.10/socket.py", line 705, in readinto
    return self._sock.recv_into(b)
  File "/usr/local/Cellar/python@3.10/3.10.0_2/Frameworks/Python.framework/Versions/3.10/lib/python3.10/ssl.py", line 1273, in recv_into
    return self.read(nbytes, buffer)
  File "/usr/local/Cellar/python@3.10/3.10.0_2/Frameworks/Python.framework/Versions/3.10/lib/python3.10/ssl.py", line 1129, in read
    return self._sslobj.read(len, buffer)
TimeoutError: The read operation timed out
20/10/21 (19:15:17) | ERROR: The read operation timed out
Traceback (most recent call last):
  File "/usr/local/bin/bpytop", line 5009, in _checker
    with urllib.request.urlopen("https://github.com/aristocratos/bpytop/raw/master/bpytop.py", timeout=5) as source: # type: ignore
  File "/usr/local/Cellar/python@3.10/3.10.0_2/Frameworks/Python.framework/Versions/3.10/lib/python3.10/urllib/request.py", line 216, in urlopen
    return opener.open(url, data, timeout)
  File "/usr/local/Cellar/python@3.10/3.10.0_2/Frameworks/Python.framework/Versions/3.10/lib/python3.10/urllib/request.py", line 519, in open
    response = self._open(req, data)
  File "/usr/local/Cellar/python@3.10/3.10.0_2/Frameworks/Python.framework/Versions/3.10/lib/python3.10/urllib/request.py", line 536, in _open
    result = self._call_chain(self.handle_open, protocol, protocol +
  File "/usr/local/Cellar/python@3.10/3.10.0_2/Frameworks/Python.framework/Versions/3.10/lib/python3.10/urllib/request.py", line 496, in _call_chain
    result = func(*args)
  File "/usr/local/Cellar/python@3.10/3.10.0_2/Frameworks/Python.framework/Versions/3.10/lib/python3.10/urllib/request.py", line 1391, in https_open
    return self.do_open(http.client.HTTPSConnection, req,
  File "/usr/local/Cellar/python@3.10/3.10.0_2/Frameworks/Python.framework/Versions/3.10/lib/python3.10/urllib/request.py", line 1352, in do_open
    r = h.getresponse()
  File "/usr/local/Cellar/python@3.10/3.10.0_2/Frameworks/Python.framework/Versions/3.10/lib/python3.10/http/client.py", line 1368, in getresponse
    response.begin()
  File "/usr/local/Cellar/python@3.10/3.10.0_2/Frameworks/Python.framework/Versions/3.10/lib/python3.10/http/client.py", line 317, in begin
    version, status, reason = self._read_status()
  File "/usr/local/Cellar/python@3.10/3.10.0_2/Frameworks/Python.framework/Versions/3.10/lib/python3.10/http/client.py", line 278, in _read_status
    line = str(self.fp.readline(_MAXLINE + 1), "iso-8859-1")
  File "/usr/local/Cellar/python@3.10/3.10.0_2/Frameworks/Python.framework/Versions/3.10/lib/python3.10/socket.py", line 705, in readinto
    return self._sock.recv_into(b)
  File "/usr/local/Cellar/python@3.10/3.10.0_2/Frameworks/Python.framework/Versions/3.10/lib/python3.10/ssl.py", line 1273, in recv_into
    return self.read(nbytes, buffer)
  File "/usr/local/Cellar/python@3.10/3.10.0_2/Frameworks/Python.framework/Versions/3.10/lib/python3.10/ssl.py", line 1129, in read
    return self._sslobj.read(len, buffer)
TimeoutError: The read operation timed out
20/10/21 (19:17:29) | ERROR: <urlopen error timed out>
Traceback (most recent call last):
  File "/usr/local/Cellar/python@3.10/3.10.0_2/Frameworks/Python.framework/Versions/3.10/lib/python3.10/urllib/request.py", line 1348, in do_open
    h.request(req.get_method(), req.selector, req.data, headers,
  File "/usr/local/Cellar/python@3.10/3.10.0_2/Frameworks/Python.framework/Versions/3.10/lib/python3.10/http/client.py", line 1276, in request
    self._send_request(method, url, body, headers, encode_chunked)
  File "/usr/local/Cellar/python@3.10/3.10.0_2/Frameworks/Python.framework/Versions/3.10/lib/python3.10/http/client.py", line 1322, in _send_request
    self.endheaders(body, encode_chunked=encode_chunked)
  File "/usr/local/Cellar/python@3.10/3.10.0_2/Frameworks/Python.framework/Versions/3.10/lib/python3.10/http/client.py", line 1271, in endheaders
    self._send_output(message_body, encode_chunked=encode_chunked)
  File "/usr/local/Cellar/python@3.10/3.10.0_2/Frameworks/Python.framework/Versions/3.10/lib/python3.10/http/client.py", line 1031, in _send_output
    self.send(msg)
  File "/usr/local/Cellar/python@3.10/3.10.0_2/Frameworks/Python.framework/Versions/3.10/lib/python3.10/http/client.py", line 969, in send
    self.connect()
  File "/usr/local/Cellar/python@3.10/3.10.0_2/Frameworks/Python.framework/Versions/3.10/lib/python3.10/http/client.py", line 1441, in connect
    super().connect()
  File "/usr/local/Cellar/python@3.10/3.10.0_2/Frameworks/Python.framework/Versions/3.10/lib/python3.10/http/client.py", line 940, in connect
    self.sock = self._create_connection(
  File "/usr/local/Cellar/python@3.10/3.10.0_2/Frameworks/Python.framework/Versions/3.10/lib/python3.10/socket.py", line 845, in create_connection
    raise err
  File "/usr/local/Cellar/python@3.10/3.10.0_2/Frameworks/Python.framework/Versions/3.10/lib/python3.10/socket.py", line 833, in create_connection
    sock.connect(sa)
TimeoutError: timed out

During handling of the above exception, another exception occurred:

Traceback (most recent call last):
  File "/usr/local/bin/bpytop", line 5009, in _checker
    with urllib.request.urlopen("https://github.com/aristocratos/bpytop/raw/master/bpytop.py", timeout=5) as source: # type: ignore
  File "/usr/local/Cellar/python@3.10/3.10.0_2/Frameworks/Python.framework/Versions/3.10/lib/python3.10/urllib/request.py", line 216, in urlopen
    return opener.open(url, data, timeout)
  File "/usr/local/Cellar/python@3.10/3.10.0_2/Frameworks/Python.framework/Versions/3.10/lib/python3.10/urllib/request.py", line 519, in open
    response = self._open(req, data)
  File "/usr/local/Cellar/python@3.10/3.10.0_2/Frameworks/Python.framework/Versions/3.10/lib/python3.10/urllib/request.py", line 536, in _open
    result = self._call_chain(self.handle_open, protocol, protocol +
  File "/usr/local/Cellar/python@3.10/3.10.0_2/Frameworks/Python.framework/Versions/3.10/lib/python3.10/urllib/request.py", line 496, in _call_chain
    result = func(*args)
  File "/usr/local/Cellar/python@3.10/3.10.0_2/Frameworks/Python.framework/Versions/3.10/lib/python3.10/urllib/request.py", line 1391, in https_open
    return self.do_open(http.client.HTTPSConnection, req,
  File "/usr/local/Cellar/python@3.10/3.10.0_2/Frameworks/Python.framework/Versions/3.10/lib/python3.10/urllib/request.py", line 1351, in do_open
    raise URLError(err)
urllib.error.URLError: <urlopen error timed out>
20/10/21 (19:23:02) | ERROR: The read operation timed out
Traceback (most recent call last):
  File "/usr/local/bin/bpytop", line 5009, in _checker
    with urllib.request.urlopen("https://github.com/aristocratos/bpytop/raw/master/bpytop.py", timeout=5) as source: # type: ignore
  File "/usr/local/Cellar/python@3.10/3.10.0_2/Frameworks/Python.framework/Versions/3.10/lib/python3.10/urllib/request.py", line 216, in urlopen
    return opener.open(url, data, timeout)
  File "/usr/local/Cellar/python@3.10/3.10.0_2/Frameworks/Python.framework/Versions/3.10/lib/python3.10/urllib/request.py", line 519, in open
    response = self._open(req, data)
  File "/usr/local/Cellar/python@3.10/3.10.0_2/Frameworks/Python.framework/Versions/3.10/lib/python3.10/urllib/request.py", line 536, in _open
    result = self._call_chain(self.handle_open, protocol, protocol +
  File "/usr/local/Cellar/python@3.10/3.10.0_2/Frameworks/Python.framework/Versions/3.10/lib/python3.10/urllib/request.py", line 496, in _call_chain
    result = func(*args)
  File "/usr/local/Cellar/python@3.10/3.10.0_2/Frameworks/Python.framework/Versions/3.10/lib/python3.10/urllib/request.py", line 1391, in https_open
    return self.do_open(http.client.HTTPSConnection, req,
  File "/usr/local/Cellar/python@3.10/3.10.0_2/Frameworks/Python.framework/Versions/3.10/lib/python3.10/urllib/request.py", line 1352, in do_open
    r = h.getresponse()
  File "/usr/local/Cellar/python@3.10/3.10.0_2/Frameworks/Python.framework/Versions/3.10/lib/python3.10/http/client.py", line 1368, in getresponse
    response.begin()
  File "/usr/local/Cellar/python@3.10/3.10.0_2/Frameworks/Python.framework/Versions/3.10/lib/python3.10/http/client.py", line 317, in begin
    version, status, reason = self._read_status()
  File "/usr/local/Cellar/python@3.10/3.10.0_2/Frameworks/Python.framework/Versions/3.10/lib/python3.10/http/client.py", line 278, in _read_status
    line = str(self.fp.readline(_MAXLINE + 1), "iso-8859-1")
  File "/usr/local/Cellar/python@3.10/3.10.0_2/Frameworks/Python.framework/Versions/3.10/lib/python3.10/socket.py", line 705, in readinto
    return self._sock.recv_into(b)
  File "/usr/local/Cellar/python@3.10/3.10.0_2/Frameworks/Python.framework/Versions/3.10/lib/python3.10/ssl.py", line 1273, in recv_into
    return self.read(nbytes, buffer)
  File "/usr/local/Cellar/python@3.10/3.10.0_2/Frameworks/Python.framework/Versions/3.10/lib/python3.10/ssl.py", line 1129, in read
    return self._sslobj.read(len, buffer)
TimeoutError: The read operation timed out
20/10/21 (19:23:08) | ERROR: <urlopen error timed out>
Traceback (most recent call last):
  File "/usr/local/Cellar/python@3.10/3.10.0_2/Frameworks/Python.framework/Versions/3.10/lib/python3.10/urllib/request.py", line 1348, in do_open
    h.request(req.get_method(), req.selector, req.data, headers,
  File "/usr/local/Cellar/python@3.10/3.10.0_2/Frameworks/Python.framework/Versions/3.10/lib/python3.10/http/client.py", line 1276, in request
    self._send_request(method, url, body, headers, encode_chunked)
  File "/usr/local/Cellar/python@3.10/3.10.0_2/Frameworks/Python.framework/Versions/3.10/lib/python3.10/http/client.py", line 1322, in _send_request
    self.endheaders(body, encode_chunked=encode_chunked)
  File "/usr/local/Cellar/python@3.10/3.10.0_2/Frameworks/Python.framework/Versions/3.10/lib/python3.10/http/client.py", line 1271, in endheaders
    self._send_output(message_body, encode_chunked=encode_chunked)
  File "/usr/local/Cellar/python@3.10/3.10.0_2/Frameworks/Python.framework/Versions/3.10/lib/python3.10/http/client.py", line 1031, in _send_output
    self.send(msg)
  File "/usr/local/Cellar/python@3.10/3.10.0_2/Frameworks/Python.framework/Versions/3.10/lib/python3.10/http/client.py", line 969, in send
    self.connect()
  File "/usr/local/Cellar/python@3.10/3.10.0_2/Frameworks/Python.framework/Versions/3.10/lib/python3.10/http/client.py", line 1441, in connect
    super().connect()
  File "/usr/local/Cellar/python@3.10/3.10.0_2/Frameworks/Python.framework/Versions/3.10/lib/python3.10/http/client.py", line 940, in connect
    self.sock = self._create_connection(
  File "/usr/local/Cellar/python@3.10/3.10.0_2/Frameworks/Python.framework/Versions/3.10/lib/python3.10/socket.py", line 845, in create_connection
    raise err
  File "/usr/local/Cellar/python@3.10/3.10.0_2/Frameworks/Python.framework/Versions/3.10/lib/python3.10/socket.py", line 833, in create_connection
    sock.connect(sa)
TimeoutError: timed out

During handling of the above exception, another exception occurred:

Traceback (most recent call last):
  File "/usr/local/bin/bpytop", line 5009, in _checker
    with urllib.request.urlopen("https://github.com/aristocratos/bpytop/raw/master/bpytop.py", timeout=5) as source: # type: ignore
  File "/usr/local/Cellar/python@3.10/3.10.0_2/Frameworks/Python.framework/Versions/3.10/lib/python3.10/urllib/request.py", line 216, in urlopen
    return opener.open(url, data, timeout)
  File "/usr/local/Cellar/python@3.10/3.10.0_2/Frameworks/Python.framework/Versions/3.10/lib/python3.10/urllib/request.py", line 519, in open
    response = self._open(req, data)
  File "/usr/local/Cellar/python@3.10/3.10.0_2/Frameworks/Python.framework/Versions/3.10/lib/python3.10/urllib/request.py", line 536, in _open
    result = self._call_chain(self.handle_open, protocol, protocol +
  File "/usr/local/Cellar/python@3.10/3.10.0_2/Frameworks/Python.framework/Versions/3.10/lib/python3.10/urllib/request.py", line 496, in _call_chain
    result = func(*args)
  File "/usr/local/Cellar/python@3.10/3.10.0_2/Frameworks/Python.framework/Versions/3.10/lib/python3.10/urllib/request.py", line 1391, in https_open
    return self.do_open(http.client.HTTPSConnection, req,
  File "/usr/local/Cellar/python@3.10/3.10.0_2/Frameworks/Python.framework/Versions/3.10/lib/python3.10/urllib/request.py", line 1351, in do_open
    raise URLError(err)
urllib.error.URLError: <urlopen error timed out>
20/10/21 (19:23:20) | ERROR: <urlopen error timed out>
Traceback (most recent call last):
  File "/usr/local/Cellar/python@3.10/3.10.0_2/Frameworks/Python.framework/Versions/3.10/lib/python3.10/urllib/request.py", line 1348, in do_open
    h.request(req.get_method(), req.selector, req.data, headers,
  File "/usr/local/Cellar/python@3.10/3.10.0_2/Frameworks/Python.framework/Versions/3.10/lib/python3.10/http/client.py", line 1276, in request
    self._send_request(method, url, body, headers, encode_chunked)
  File "/usr/local/Cellar/python@3.10/3.10.0_2/Frameworks/Python.framework/Versions/3.10/lib/python3.10/http/client.py", line 1322, in _send_request
    self.endheaders(body, encode_chunked=encode_chunked)
  File "/usr/local/Cellar/python@3.10/3.10.0_2/Frameworks/Python.framework/Versions/3.10/lib/python3.10/http/client.py", line 1271, in endheaders
    self._send_output(message_body, encode_chunked=encode_chunked)
  File "/usr/local/Cellar/python@3.10/3.10.0_2/Frameworks/Python.framework/Versions/3.10/lib/python3.10/http/client.py", line 1031, in _send_output
    self.send(msg)
  File "/usr/local/Cellar/python@3.10/3.10.0_2/Frameworks/Python.framework/Versions/3.10/lib/python3.10/http/client.py", line 969, in send
    self.connect()
  File "/usr/local/Cellar/python@3.10/3.10.0_2/Frameworks/Python.framework/Versions/3.10/lib/python3.10/http/client.py", line 1441, in connect
    super().connect()
  File "/usr/local/Cellar/python@3.10/3.10.0_2/Frameworks/Python.framework/Versions/3.10/lib/python3.10/http/client.py", line 940, in connect
    self.sock = self._create_connection(
  File "/usr/local/Cellar/python@3.10/3.10.0_2/Frameworks/Python.framework/Versions/3.10/lib/python3.10/socket.py", line 845, in create_connection
    raise err
  File "/usr/local/Cellar/python@3.10/3.10.0_2/Frameworks/Python.framework/Versions/3.10/lib/python3.10/socket.py", line 833, in create_connection
    sock.connect(sa)
TimeoutError: timed out

During handling of the above exception, another exception occurred:

Traceback (most recent call last):
  File "/usr/local/bin/bpytop", line 5009, in _checker
    with urllib.request.urlopen("https://github.com/aristocratos/bpytop/raw/master/bpytop.py", timeout=5) as source: # type: ignore
  File "/usr/local/Cellar/python@3.10/3.10.0_2/Frameworks/Python.framework/Versions/3.10/lib/python3.10/urllib/request.py", line 216, in urlopen
    return opener.open(url, data, timeout)
  File "/usr/local/Cellar/python@3.10/3.10.0_2/Frameworks/Python.framework/Versions/3.10/lib/python3.10/urllib/request.py", line 519, in open
    response = self._open(req, data)
  File "/usr/local/Cellar/python@3.10/3.10.0_2/Frameworks/Python.framework/Versions/3.10/lib/python3.10/urllib/request.py", line 536, in _open
    result = self._call_chain(self.handle_open, protocol, protocol +
  File "/usr/local/Cellar/python@3.10/3.10.0_2/Frameworks/Python.framework/Versions/3.10/lib/python3.10/urllib/request.py", line 496, in _call_chain
    result = func(*args)
  File "/usr/local/Cellar/python@3.10/3.10.0_2/Frameworks/Python.framework/Versions/3.10/lib/python3.10/urllib/request.py", line 1391, in https_open
    return self.do_open(http.client.HTTPSConnection, req,
  File "/usr/local/Cellar/python@3.10/3.10.0_2/Frameworks/Python.framework/Versions/3.10/lib/python3.10/urllib/request.py", line 1351, in do_open
    raise URLError(err)
urllib.error.URLError: <urlopen error timed out>
20/10/21 (19:23:36) | ERROR: The read operation timed out
Traceback (most recent call last):
  File "/usr/local/bin/bpytop", line 5009, in _checker
    with urllib.request.urlopen("https://github.com/aristocratos/bpytop/raw/master/bpytop.py", timeout=5) as source: # type: ignore
  File "/usr/local/Cellar/python@3.10/3.10.0_2/Frameworks/Python.framework/Versions/3.10/lib/python3.10/urllib/request.py", line 216, in urlopen
    return opener.open(url, data, timeout)
  File "/usr/local/Cellar/python@3.10/3.10.0_2/Frameworks/Python.framework/Versions/3.10/lib/python3.10/urllib/request.py", line 519, in open
    response = self._open(req, data)
  File "/usr/local/Cellar/python@3.10/3.10.0_2/Frameworks/Python.framework/Versions/3.10/lib/python3.10/urllib/request.py", line 536, in _open
    result = self._call_chain(self.handle_open, protocol, protocol +
  File "/usr/local/Cellar/python@3.10/3.10.0_2/Frameworks/Python.framework/Versions/3.10/lib/python3.10/urllib/request.py", line 496, in _call_chain
    result = func(*args)
  File "/usr/local/Cellar/python@3.10/3.10.0_2/Frameworks/Python.framework/Versions/3.10/lib/python3.10/urllib/request.py", line 1391, in https_open
    return self.do_open(http.client.HTTPSConnection, req,
  File "/usr/local/Cellar/python@3.10/3.10.0_2/Frameworks/Python.framework/Versions/3.10/lib/python3.10/urllib/request.py", line 1352, in do_open
    r = h.getresponse()
  File "/usr/local/Cellar/python@3.10/3.10.0_2/Frameworks/Python.framework/Versions/3.10/lib/python3.10/http/client.py", line 1368, in getresponse
    response.begin()
  File "/usr/local/Cellar/python@3.10/3.10.0_2/Frameworks/Python.framework/Versions/3.10/lib/python3.10/http/client.py", line 317, in begin
    version, status, reason = self._read_status()
  File "/usr/local/Cellar/python@3.10/3.10.0_2/Frameworks/Python.framework/Versions/3.10/lib/python3.10/http/client.py", line 278, in _read_status
    line = str(self.fp.readline(_MAXLINE + 1), "iso-8859-1")
  File "/usr/local/Cellar/python@3.10/3.10.0_2/Frameworks/Python.framework/Versions/3.10/lib/python3.10/socket.py", line 705, in readinto
    return self._sock.recv_into(b)
  File "/usr/local/Cellar/python@3.10/3.10.0_2/Frameworks/Python.framework/Versions/3.10/lib/python3.10/ssl.py", line 1273, in recv_into
    return self.read(nbytes, buffer)
  File "/usr/local/Cellar/python@3.10/3.10.0_2/Frameworks/Python.framework/Versions/3.10/lib/python3.10/ssl.py", line 1129, in read
    return self._sslobj.read(len, buffer)
TimeoutError: The read operation timed out
21/10/21 (01:29:30) | ERROR: The read operation timed out
Traceback (most recent call last):
  File "/usr/local/bin/bpytop", line 5009, in _checker
    with urllib.request.urlopen("https://github.com/aristocratos/bpytop/raw/master/bpytop.py", timeout=5) as source: # type: ignore
  File "/usr/local/Cellar/python@3.10/3.10.0_2/Frameworks/Python.framework/Versions/3.10/lib/python3.10/urllib/request.py", line 216, in urlopen
    return opener.open(url, data, timeout)
  File "/usr/local/Cellar/python@3.10/3.10.0_2/Frameworks/Python.framework/Versions/3.10/lib/python3.10/urllib/request.py", line 525, in open
    response = meth(req, response)
  File "/usr/local/Cellar/python@3.10/3.10.0_2/Frameworks/Python.framework/Versions/3.10/lib/python3.10/urllib/request.py", line 634, in http_response
    response = self.parent.error(
  File "/usr/local/Cellar/python@3.10/3.10.0_2/Frameworks/Python.framework/Versions/3.10/lib/python3.10/urllib/request.py", line 557, in error
    result = self._call_chain(*args)
  File "/usr/local/Cellar/python@3.10/3.10.0_2/Frameworks/Python.framework/Versions/3.10/lib/python3.10/urllib/request.py", line 496, in _call_chain
    result = func(*args)
  File "/usr/local/Cellar/python@3.10/3.10.0_2/Frameworks/Python.framework/Versions/3.10/lib/python3.10/urllib/request.py", line 749, in http_error_302
    return self.parent.open(new, timeout=req.timeout)
  File "/usr/local/Cellar/python@3.10/3.10.0_2/Frameworks/Python.framework/Versions/3.10/lib/python3.10/urllib/request.py", line 519, in open
    response = self._open(req, data)
  File "/usr/local/Cellar/python@3.10/3.10.0_2/Frameworks/Python.framework/Versions/3.10/lib/python3.10/urllib/request.py", line 536, in _open
    result = self._call_chain(self.handle_open, protocol, protocol +
  File "/usr/local/Cellar/python@3.10/3.10.0_2/Frameworks/Python.framework/Versions/3.10/lib/python3.10/urllib/request.py", line 496, in _call_chain
    result = func(*args)
  File "/usr/local/Cellar/python@3.10/3.10.0_2/Frameworks/Python.framework/Versions/3.10/lib/python3.10/urllib/request.py", line 1391, in https_open
    return self.do_open(http.client.HTTPSConnection, req,
  File "/usr/local/Cellar/python@3.10/3.10.0_2/Frameworks/Python.framework/Versions/3.10/lib/python3.10/urllib/request.py", line 1352, in do_open
    r = h.getresponse()
  File "/usr/local/Cellar/python@3.10/3.10.0_2/Frameworks/Python.framework/Versions/3.10/lib/python3.10/http/client.py", line 1368, in getresponse
    response.begin()
  File "/usr/local/Cellar/python@3.10/3.10.0_2/Frameworks/Python.framework/Versions/3.10/lib/python3.10/http/client.py", line 317, in begin
    version, status, reason = self._read_status()
  File "/usr/local/Cellar/python@3.10/3.10.0_2/Frameworks/Python.framework/Versions/3.10/lib/python3.10/http/client.py", line 278, in _read_status
    line = str(self.fp.readline(_MAXLINE + 1), "iso-8859-1")
  File "/usr/local/Cellar/python@3.10/3.10.0_2/Frameworks/Python.framework/Versions/3.10/lib/python3.10/socket.py", line 705, in readinto
    return self._sock.recv_into(b)
  File "/usr/local/Cellar/python@3.10/3.10.0_2/Frameworks/Python.framework/Versions/3.10/lib/python3.10/ssl.py", line 1273, in recv_into
    return self.read(nbytes, buffer)
  File "/usr/local/Cellar/python@3.10/3.10.0_2/Frameworks/Python.framework/Versions/3.10/lib/python3.10/ssl.py", line 1129, in read
    return self._sslobj.read(len, buffer)
TimeoutError: The read operation timed out
21/10/21 (01:33:35) | ERROR: The read operation timed out
Traceback (most recent call last):
  File "/usr/local/bin/bpytop", line 5009, in _checker
    with urllib.request.urlopen("https://github.com/aristocratos/bpytop/raw/master/bpytop.py", timeout=5) as source: # type: ignore
  File "/usr/local/Cellar/python@3.10/3.10.0_2/Frameworks/Python.framework/Versions/3.10/lib/python3.10/urllib/request.py", line 216, in urlopen
    return opener.open(url, data, timeout)
  File "/usr/local/Cellar/python@3.10/3.10.0_2/Frameworks/Python.framework/Versions/3.10/lib/python3.10/urllib/request.py", line 519, in open
    response = self._open(req, data)
  File "/usr/local/Cellar/python@3.10/3.10.0_2/Frameworks/Python.framework/Versions/3.10/lib/python3.10/urllib/request.py", line 536, in _open
    result = self._call_chain(self.handle_open, protocol, protocol +
  File "/usr/local/Cellar/python@3.10/3.10.0_2/Frameworks/Python.framework/Versions/3.10/lib/python3.10/urllib/request.py", line 496, in _call_chain
    result = func(*args)
  File "/usr/local/Cellar/python@3.10/3.10.0_2/Frameworks/Python.framework/Versions/3.10/lib/python3.10/urllib/request.py", line 1391, in https_open
    return self.do_open(http.client.HTTPSConnection, req,
  File "/usr/local/Cellar/python@3.10/3.10.0_2/Frameworks/Python.framework/Versions/3.10/lib/python3.10/urllib/request.py", line 1352, in do_open
    r = h.getresponse()
  File "/usr/local/Cellar/python@3.10/3.10.0_2/Frameworks/Python.framework/Versions/3.10/lib/python3.10/http/client.py", line 1368, in getresponse
    response.begin()
  File "/usr/local/Cellar/python@3.10/3.10.0_2/Frameworks/Python.framework/Versions/3.10/lib/python3.10/http/client.py", line 317, in begin
    version, status, reason = self._read_status()
  File "/usr/local/Cellar/python@3.10/3.10.0_2/Frameworks/Python.framework/Versions/3.10/lib/python3.10/http/client.py", line 278, in _read_status
    line = str(self.fp.readline(_MAXLINE + 1), "iso-8859-1")
  File "/usr/local/Cellar/python@3.10/3.10.0_2/Frameworks/Python.framework/Versions/3.10/lib/python3.10/socket.py", line 705, in readinto
    return self._sock.recv_into(b)
  File "/usr/local/Cellar/python@3.10/3.10.0_2/Frameworks/Python.framework/Versions/3.10/lib/python3.10/ssl.py", line 1273, in recv_into
    return self.read(nbytes, buffer)
  File "/usr/local/Cellar/python@3.10/3.10.0_2/Frameworks/Python.framework/Versions/3.10/lib/python3.10/ssl.py", line 1129, in read
    return self._sslobj.read(len, buffer)
TimeoutError: The read operation timed out
21/10/21 (01:33:42) | ERROR: <urlopen error timed out>
Traceback (most recent call last):
  File "/usr/local/Cellar/python@3.10/3.10.0_2/Frameworks/Python.framework/Versions/3.10/lib/python3.10/urllib/request.py", line 1348, in do_open
    h.request(req.get_method(), req.selector, req.data, headers,
  File "/usr/local/Cellar/python@3.10/3.10.0_2/Frameworks/Python.framework/Versions/3.10/lib/python3.10/http/client.py", line 1276, in request
    self._send_request(method, url, body, headers, encode_chunked)
  File "/usr/local/Cellar/python@3.10/3.10.0_2/Frameworks/Python.framework/Versions/3.10/lib/python3.10/http/client.py", line 1322, in _send_request
    self.endheaders(body, encode_chunked=encode_chunked)
  File "/usr/local/Cellar/python@3.10/3.10.0_2/Frameworks/Python.framework/Versions/3.10/lib/python3.10/http/client.py", line 1271, in endheaders
    self._send_output(message_body, encode_chunked=encode_chunked)
  File "/usr/local/Cellar/python@3.10/3.10.0_2/Frameworks/Python.framework/Versions/3.10/lib/python3.10/http/client.py", line 1031, in _send_output
    self.send(msg)
  File "/usr/local/Cellar/python@3.10/3.10.0_2/Frameworks/Python.framework/Versions/3.10/lib/python3.10/http/client.py", line 969, in send
    self.connect()
  File "/usr/local/Cellar/python@3.10/3.10.0_2/Frameworks/Python.framework/Versions/3.10/lib/python3.10/http/client.py", line 1441, in connect
    super().connect()
  File "/usr/local/Cellar/python@3.10/3.10.0_2/Frameworks/Python.framework/Versions/3.10/lib/python3.10/http/client.py", line 940, in connect
    self.sock = self._create_connection(
  File "/usr/local/Cellar/python@3.10/3.10.0_2/Frameworks/Python.framework/Versions/3.10/lib/python3.10/socket.py", line 845, in create_connection
    raise err
  File "/usr/local/Cellar/python@3.10/3.10.0_2/Frameworks/Python.framework/Versions/3.10/lib/python3.10/socket.py", line 833, in create_connection
    sock.connect(sa)
TimeoutError: timed out

During handling of the above exception, another exception occurred:

Traceback (most recent call last):
  File "/usr/local/bin/bpytop", line 5009, in _checker
    with urllib.request.urlopen("https://github.com/aristocratos/bpytop/raw/master/bpytop.py", timeout=5) as source: # type: ignore
  File "/usr/local/Cellar/python@3.10/3.10.0_2/Frameworks/Python.framework/Versions/3.10/lib/python3.10/urllib/request.py", line 216, in urlopen
    return opener.open(url, data, timeout)
  File "/usr/local/Cellar/python@3.10/3.10.0_2/Frameworks/Python.framework/Versions/3.10/lib/python3.10/urllib/request.py", line 519, in open
    response = self._open(req, data)
  File "/usr/local/Cellar/python@3.10/3.10.0_2/Frameworks/Python.framework/Versions/3.10/lib/python3.10/urllib/request.py", line 536, in _open
    result = self._call_chain(self.handle_open, protocol, protocol +
  File "/usr/local/Cellar/python@3.10/3.10.0_2/Frameworks/Python.framework/Versions/3.10/lib/python3.10/urllib/request.py", line 496, in _call_chain
    result = func(*args)
  File "/usr/local/Cellar/python@3.10/3.10.0_2/Frameworks/Python.framework/Versions/3.10/lib/python3.10/urllib/request.py", line 1391, in https_open
    return self.do_open(http.client.HTTPSConnection, req,
  File "/usr/local/Cellar/python@3.10/3.10.0_2/Frameworks/Python.framework/Versions/3.10/lib/python3.10/urllib/request.py", line 1351, in do_open
    raise URLError(err)
urllib.error.URLError: <urlopen error timed out>
21/10/21 (20:57:14) | ERROR: The read operation timed out
Traceback (most recent call last):
  File "/usr/local/bin/bpytop", line 5009, in _checker
    with urllib.request.urlopen("https://github.com/aristocratos/bpytop/raw/master/bpytop.py", timeout=5) as source: # type: ignore
  File "/usr/local/Cellar/python@3.10/3.10.0_2/Frameworks/Python.framework/Versions/3.10/lib/python3.10/urllib/request.py", line 216, in urlopen
    return opener.open(url, data, timeout)
  File "/usr/local/Cellar/python@3.10/3.10.0_2/Frameworks/Python.framework/Versions/3.10/lib/python3.10/urllib/request.py", line 519, in open
    response = self._open(req, data)
  File "/usr/local/Cellar/python@3.10/3.10.0_2/Frameworks/Python.framework/Versions/3.10/lib/python3.10/urllib/request.py", line 536, in _open
    result = self._call_chain(self.handle_open, protocol, protocol +
  File "/usr/local/Cellar/python@3.10/3.10.0_2/Frameworks/Python.framework/Versions/3.10/lib/python3.10/urllib/request.py", line 496, in _call_chain
    result = func(*args)
  File "/usr/local/Cellar/python@3.10/3.10.0_2/Frameworks/Python.framework/Versions/3.10/lib/python3.10/urllib/request.py", line 1391, in https_open
    return self.do_open(http.client.HTTPSConnection, req,
  File "/usr/local/Cellar/python@3.10/3.10.0_2/Frameworks/Python.framework/Versions/3.10/lib/python3.10/urllib/request.py", line 1352, in do_open
    r = h.getresponse()
  File "/usr/local/Cellar/python@3.10/3.10.0_2/Frameworks/Python.framework/Versions/3.10/lib/python3.10/http/client.py", line 1368, in getresponse
    response.begin()
  File "/usr/local/Cellar/python@3.10/3.10.0_2/Frameworks/Python.framework/Versions/3.10/lib/python3.10/http/client.py", line 317, in begin
    version, status, reason = self._read_status()
  File "/usr/local/Cellar/python@3.10/3.10.0_2/Frameworks/Python.framework/Versions/3.10/lib/python3.10/http/client.py", line 278, in _read_status
    line = str(self.fp.readline(_MAXLINE + 1), "iso-8859-1")
  File "/usr/local/Cellar/python@3.10/3.10.0_2/Frameworks/Python.framework/Versions/3.10/lib/python3.10/socket.py", line 705, in readinto
    return self._sock.recv_into(b)
  File "/usr/local/Cellar/python@3.10/3.10.0_2/Frameworks/Python.framework/Versions/3.10/lib/python3.10/ssl.py", line 1273, in recv_into
    return self.read(nbytes, buffer)
  File "/usr/local/Cellar/python@3.10/3.10.0_2/Frameworks/Python.framework/Versions/3.10/lib/python3.10/ssl.py", line 1129, in read
    return self._sslobj.read(len, buffer)
TimeoutError: The read operation timed out
21/10/21 (20:59:51) | ERROR: <urlopen error timed out>
Traceback (most recent call last):
  File "/usr/local/Cellar/python@3.10/3.10.0_2/Frameworks/Python.framework/Versions/3.10/lib/python3.10/urllib/request.py", line 1348, in do_open
    h.request(req.get_method(), req.selector, req.data, headers,
  File "/usr/local/Cellar/python@3.10/3.10.0_2/Frameworks/Python.framework/Versions/3.10/lib/python3.10/http/client.py", line 1276, in request
    self._send_request(method, url, body, headers, encode_chunked)
  File "/usr/local/Cellar/python@3.10/3.10.0_2/Frameworks/Python.framework/Versions/3.10/lib/python3.10/http/client.py", line 1322, in _send_request
    self.endheaders(body, encode_chunked=encode_chunked)
  File "/usr/local/Cellar/python@3.10/3.10.0_2/Frameworks/Python.framework/Versions/3.10/lib/python3.10/http/client.py", line 1271, in endheaders
    self._send_output(message_body, encode_chunked=encode_chunked)
  File "/usr/local/Cellar/python@3.10/3.10.0_2/Frameworks/Python.framework/Versions/3.10/lib/python3.10/http/client.py", line 1031, in _send_output
    self.send(msg)
  File "/usr/local/Cellar/python@3.10/3.10.0_2/Frameworks/Python.framework/Versions/3.10/lib/python3.10/http/client.py", line 969, in send
    self.connect()
  File "/usr/local/Cellar/python@3.10/3.10.0_2/Frameworks/Python.framework/Versions/3.10/lib/python3.10/http/client.py", line 1441, in connect
    super().connect()
  File "/usr/local/Cellar/python@3.10/3.10.0_2/Frameworks/Python.framework/Versions/3.10/lib/python3.10/http/client.py", line 940, in connect
    self.sock = self._create_connection(
  File "/usr/local/Cellar/python@3.10/3.10.0_2/Frameworks/Python.framework/Versions/3.10/lib/python3.10/socket.py", line 845, in create_connection
    raise err
  File "/usr/local/Cellar/python@3.10/3.10.0_2/Frameworks/Python.framework/Versions/3.10/lib/python3.10/socket.py", line 833, in create_connection
    sock.connect(sa)
TimeoutError: timed out

During handling of the above exception, another exception occurred:

Traceback (most recent call last):
  File "/usr/local/bin/bpytop", line 5009, in _checker
    with urllib.request.urlopen("https://github.com/aristocratos/bpytop/raw/master/bpytop.py", timeout=5) as source: # type: ignore
  File "/usr/local/Cellar/python@3.10/3.10.0_2/Frameworks/Python.framework/Versions/3.10/lib/python3.10/urllib/request.py", line 216, in urlopen
    return opener.open(url, data, timeout)
  File "/usr/local/Cellar/python@3.10/3.10.0_2/Frameworks/Python.framework/Versions/3.10/lib/python3.10/urllib/request.py", line 519, in open
    response = self._open(req, data)
  File "/usr/local/Cellar/python@3.10/3.10.0_2/Frameworks/Python.framework/Versions/3.10/lib/python3.10/urllib/request.py", line 536, in _open
    result = self._call_chain(self.handle_open, protocol, protocol +
  File "/usr/local/Cellar/python@3.10/3.10.0_2/Frameworks/Python.framework/Versions/3.10/lib/python3.10/urllib/request.py", line 496, in _call_chain
    result = func(*args)
  File "/usr/local/Cellar/python@3.10/3.10.0_2/Frameworks/Python.framework/Versions/3.10/lib/python3.10/urllib/request.py", line 1391, in https_open
    return self.do_open(http.client.HTTPSConnection, req,
  File "/usr/local/Cellar/python@3.10/3.10.0_2/Frameworks/Python.framework/Versions/3.10/lib/python3.10/urllib/request.py", line 1351, in do_open
    raise URLError(err)
urllib.error.URLError: <urlopen error timed out>
21/10/21 (21:19:11) | ERROR: The read operation timed out
Traceback (most recent call last):
  File "/usr/local/bin/bpytop", line 5009, in _checker
    with urllib.request.urlopen("https://github.com/aristocratos/bpytop/raw/master/bpytop.py", timeout=5) as source: # type: ignore
  File "/usr/local/Cellar/python@3.10/3.10.0_2/Frameworks/Python.framework/Versions/3.10/lib/python3.10/urllib/request.py", line 216, in urlopen
    return opener.open(url, data, timeout)
  File "/usr/local/Cellar/python@3.10/3.10.0_2/Frameworks/Python.framework/Versions/3.10/lib/python3.10/urllib/request.py", line 519, in open
    response = self._open(req, data)
  File "/usr/local/Cellar/python@3.10/3.10.0_2/Frameworks/Python.framework/Versions/3.10/lib/python3.10/urllib/request.py", line 536, in _open
    result = self._call_chain(self.handle_open, protocol, protocol +
  File "/usr/local/Cellar/python@3.10/3.10.0_2/Frameworks/Python.framework/Versions/3.10/lib/python3.10/urllib/request.py", line 496, in _call_chain
    result = func(*args)
  File "/usr/local/Cellar/python@3.10/3.10.0_2/Frameworks/Python.framework/Versions/3.10/lib/python3.10/urllib/request.py", line 1391, in https_open
    return self.do_open(http.client.HTTPSConnection, req,
  File "/usr/local/Cellar/python@3.10/3.10.0_2/Frameworks/Python.framework/Versions/3.10/lib/python3.10/urllib/request.py", line 1352, in do_open
    r = h.getresponse()
  File "/usr/local/Cellar/python@3.10/3.10.0_2/Frameworks/Python.framework/Versions/3.10/lib/python3.10/http/client.py", line 1368, in getresponse
    response.begin()
  File "/usr/local/Cellar/python@3.10/3.10.0_2/Frameworks/Python.framework/Versions/3.10/lib/python3.10/http/client.py", line 317, in begin
    version, status, reason = self._read_status()
  File "/usr/local/Cellar/python@3.10/3.10.0_2/Frameworks/Python.framework/Versions/3.10/lib/python3.10/http/client.py", line 278, in _read_status
    line = str(self.fp.readline(_MAXLINE + 1), "iso-8859-1")
  File "/usr/local/Cellar/python@3.10/3.10.0_2/Frameworks/Python.framework/Versions/3.10/lib/python3.10/socket.py", line 705, in readinto
    return self._sock.recv_into(b)
  File "/usr/local/Cellar/python@3.10/3.10.0_2/Frameworks/Python.framework/Versions/3.10/lib/python3.10/ssl.py", line 1273, in recv_into
    return self.read(nbytes, buffer)
  File "/usr/local/Cellar/python@3.10/3.10.0_2/Frameworks/Python.framework/Versions/3.10/lib/python3.10/ssl.py", line 1129, in read
    return self._sslobj.read(len, buffer)
TimeoutError: The read operation timed out
21/10/21 (22:57:07) | ERROR: <urlopen error timed out>
Traceback (most recent call last):
  File "/usr/local/Cellar/python@3.10/3.10.0_2/Frameworks/Python.framework/Versions/3.10/lib/python3.10/urllib/request.py", line 1348, in do_open
    h.request(req.get_method(), req.selector, req.data, headers,
  File "/usr/local/Cellar/python@3.10/3.10.0_2/Frameworks/Python.framework/Versions/3.10/lib/python3.10/http/client.py", line 1276, in request
    self._send_request(method, url, body, headers, encode_chunked)
  File "/usr/local/Cellar/python@3.10/3.10.0_2/Frameworks/Python.framework/Versions/3.10/lib/python3.10/http/client.py", line 1322, in _send_request
    self.endheaders(body, encode_chunked=encode_chunked)
  File "/usr/local/Cellar/python@3.10/3.10.0_2/Frameworks/Python.framework/Versions/3.10/lib/python3.10/http/client.py", line 1271, in endheaders
    self._send_output(message_body, encode_chunked=encode_chunked)
  File "/usr/local/Cellar/python@3.10/3.10.0_2/Frameworks/Python.framework/Versions/3.10/lib/python3.10/http/client.py", line 1031, in _send_output
    self.send(msg)
  File "/usr/local/Cellar/python@3.10/3.10.0_2/Frameworks/Python.framework/Versions/3.10/lib/python3.10/http/client.py", line 969, in send
    self.connect()
  File "/usr/local/Cellar/python@3.10/3.10.0_2/Frameworks/Python.framework/Versions/3.10/lib/python3.10/http/client.py", line 1441, in connect
    super().connect()
  File "/usr/local/Cellar/python@3.10/3.10.0_2/Frameworks/Python.framework/Versions/3.10/lib/python3.10/http/client.py", line 940, in connect
    self.sock = self._create_connection(
  File "/usr/local/Cellar/python@3.10/3.10.0_2/Frameworks/Python.framework/Versions/3.10/lib/python3.10/socket.py", line 845, in create_connection
    raise err
  File "/usr/local/Cellar/python@3.10/3.10.0_2/Frameworks/Python.framework/Versions/3.10/lib/python3.10/socket.py", line 833, in create_connection
    sock.connect(sa)
TimeoutError: timed out

During handling of the above exception, another exception occurred:

Traceback (most recent call last):
  File "/usr/local/bin/bpytop", line 5009, in _checker
    with urllib.request.urlopen("https://github.com/aristocratos/bpytop/raw/master/bpytop.py", timeout=5) as source: # type: ignore
  File "/usr/local/Cellar/python@3.10/3.10.0_2/Frameworks/Python.framework/Versions/3.10/lib/python3.10/urllib/request.py", line 216, in urlopen
    return opener.open(url, data, timeout)
  File "/usr/local/Cellar/python@3.10/3.10.0_2/Frameworks/Python.framework/Versions/3.10/lib/python3.10/urllib/request.py", line 519, in open
    response = self._open(req, data)
  File "/usr/local/Cellar/python@3.10/3.10.0_2/Frameworks/Python.framework/Versions/3.10/lib/python3.10/urllib/request.py", line 536, in _open
    result = self._call_chain(self.handle_open, protocol, protocol +
  File "/usr/local/Cellar/python@3.10/3.10.0_2/Frameworks/Python.framework/Versions/3.10/lib/python3.10/urllib/request.py", line 496, in _call_chain
    result = func(*args)
  File "/usr/local/Cellar/python@3.10/3.10.0_2/Frameworks/Python.framework/Versions/3.10/lib/python3.10/urllib/request.py", line 1391, in https_open
    return self.do_open(http.client.HTTPSConnection, req,
  File "/usr/local/Cellar/python@3.10/3.10.0_2/Frameworks/Python.framework/Versions/3.10/lib/python3.10/urllib/request.py", line 1351, in do_open
    raise URLError(err)
urllib.error.URLError: <urlopen error timed out>
21/10/21 (23:26:43) | ERROR: <urlopen error _ssl.c:980: The handshake operation timed out>
Traceback (most recent call last):
  File "/usr/local/Cellar/python@3.10/3.10.0_2/Frameworks/Python.framework/Versions/3.10/lib/python3.10/urllib/request.py", line 1348, in do_open
    h.request(req.get_method(), req.selector, req.data, headers,
  File "/usr/local/Cellar/python@3.10/3.10.0_2/Frameworks/Python.framework/Versions/3.10/lib/python3.10/http/client.py", line 1276, in request
    self._send_request(method, url, body, headers, encode_chunked)
  File "/usr/local/Cellar/python@3.10/3.10.0_2/Frameworks/Python.framework/Versions/3.10/lib/python3.10/http/client.py", line 1322, in _send_request
    self.endheaders(body, encode_chunked=encode_chunked)
  File "/usr/local/Cellar/python@3.10/3.10.0_2/Frameworks/Python.framework/Versions/3.10/lib/python3.10/http/client.py", line 1271, in endheaders
    self._send_output(message_body, encode_chunked=encode_chunked)
  File "/usr/local/Cellar/python@3.10/3.10.0_2/Frameworks/Python.framework/Versions/3.10/lib/python3.10/http/client.py", line 1031, in _send_output
    self.send(msg)
  File "/usr/local/Cellar/python@3.10/3.10.0_2/Frameworks/Python.framework/Versions/3.10/lib/python3.10/http/client.py", line 969, in send
    self.connect()
  File "/usr/local/Cellar/python@3.10/3.10.0_2/Frameworks/Python.framework/Versions/3.10/lib/python3.10/http/client.py", line 1448, in connect
    self.sock = self._context.wrap_socket(self.sock,
  File "/usr/local/Cellar/python@3.10/3.10.0_2/Frameworks/Python.framework/Versions/3.10/lib/python3.10/ssl.py", line 512, in wrap_socket
    return self.sslsocket_class._create(
  File "/usr/local/Cellar/python@3.10/3.10.0_2/Frameworks/Python.framework/Versions/3.10/lib/python3.10/ssl.py", line 1070, in _create
    self.do_handshake()
  File "/usr/local/Cellar/python@3.10/3.10.0_2/Frameworks/Python.framework/Versions/3.10/lib/python3.10/ssl.py", line 1341, in do_handshake
    self._sslobj.do_handshake()
TimeoutError: _ssl.c:980: The handshake operation timed out

During handling of the above exception, another exception occurred:

Traceback (most recent call last):
  File "/usr/local/bin/bpytop", line 5009, in _checker
    with urllib.request.urlopen("https://github.com/aristocratos/bpytop/raw/master/bpytop.py", timeout=5) as source: # type: ignore
  File "/usr/local/Cellar/python@3.10/3.10.0_2/Frameworks/Python.framework/Versions/3.10/lib/python3.10/urllib/request.py", line 216, in urlopen
    return opener.open(url, data, timeout)
  File "/usr/local/Cellar/python@3.10/3.10.0_2/Frameworks/Python.framework/Versions/3.10/lib/python3.10/urllib/request.py", line 525, in open
    response = meth(req, response)
  File "/usr/local/Cellar/python@3.10/3.10.0_2/Frameworks/Python.framework/Versions/3.10/lib/python3.10/urllib/request.py", line 634, in http_response
    response = self.parent.error(
  File "/usr/local/Cellar/python@3.10/3.10.0_2/Frameworks/Python.framework/Versions/3.10/lib/python3.10/urllib/request.py", line 557, in error
    result = self._call_chain(*args)
  File "/usr/local/Cellar/python@3.10/3.10.0_2/Frameworks/Python.framework/Versions/3.10/lib/python3.10/urllib/request.py", line 496, in _call_chain
    result = func(*args)
  File "/usr/local/Cellar/python@3.10/3.10.0_2/Frameworks/Python.framework/Versions/3.10/lib/python3.10/urllib/request.py", line 749, in http_error_302
    return self.parent.open(new, timeout=req.timeout)
  File "/usr/local/Cellar/python@3.10/3.10.0_2/Frameworks/Python.framework/Versions/3.10/lib/python3.10/urllib/request.py", line 519, in open
    response = self._open(req, data)
  File "/usr/local/Cellar/python@3.10/3.10.0_2/Frameworks/Python.framework/Versions/3.10/lib/python3.10/urllib/request.py", line 536, in _open
    result = self._call_chain(self.handle_open, protocol, protocol +
  File "/usr/local/Cellar/python@3.10/3.10.0_2/Frameworks/Python.framework/Versions/3.10/lib/python3.10/urllib/request.py", line 496, in _call_chain
    result = func(*args)
  File "/usr/local/Cellar/python@3.10/3.10.0_2/Frameworks/Python.framework/Versions/3.10/lib/python3.10/urllib/request.py", line 1391, in https_open
    return self.do_open(http.client.HTTPSConnection, req,
  File "/usr/local/Cellar/python@3.10/3.10.0_2/Frameworks/Python.framework/Versions/3.10/lib/python3.10/urllib/request.py", line 1351, in do_open
    raise URLError(err)
urllib.error.URLError: <urlopen error _ssl.c:980: The handshake operation timed out>
22/10/21 (01:11:57) | ERROR: <urlopen error _ssl.c:980: The handshake operation timed out>
Traceback (most recent call last):
  File "/usr/local/Cellar/python@3.10/3.10.0_2/Frameworks/Python.framework/Versions/3.10/lib/python3.10/urllib/request.py", line 1348, in do_open
    h.request(req.get_method(), req.selector, req.data, headers,
  File "/usr/local/Cellar/python@3.10/3.10.0_2/Frameworks/Python.framework/Versions/3.10/lib/python3.10/http/client.py", line 1276, in request
    self._send_request(method, url, body, headers, encode_chunked)
  File "/usr/local/Cellar/python@3.10/3.10.0_2/Frameworks/Python.framework/Versions/3.10/lib/python3.10/http/client.py", line 1322, in _send_request
    self.endheaders(body, encode_chunked=encode_chunked)
  File "/usr/local/Cellar/python@3.10/3.10.0_2/Frameworks/Python.framework/Versions/3.10/lib/python3.10/http/client.py", line 1271, in endheaders
    self._send_output(message_body, encode_chunked=encode_chunked)
  File "/usr/local/Cellar/python@3.10/3.10.0_2/Frameworks/Python.framework/Versions/3.10/lib/python3.10/http/client.py", line 1031, in _send_output
    self.send(msg)
  File "/usr/local/Cellar/python@3.10/3.10.0_2/Frameworks/Python.framework/Versions/3.10/lib/python3.10/http/client.py", line 969, in send
    self.connect()
  File "/usr/local/Cellar/python@3.10/3.10.0_2/Frameworks/Python.framework/Versions/3.10/lib/python3.10/http/client.py", line 1448, in connect
    self.sock = self._context.wrap_socket(self.sock,
  File "/usr/local/Cellar/python@3.10/3.10.0_2/Frameworks/Python.framework/Versions/3.10/lib/python3.10/ssl.py", line 512, in wrap_socket
    return self.sslsocket_class._create(
  File "/usr/local/Cellar/python@3.10/3.10.0_2/Frameworks/Python.framework/Versions/3.10/lib/python3.10/ssl.py", line 1070, in _create
    self.do_handshake()
  File "/usr/local/Cellar/python@3.10/3.10.0_2/Frameworks/Python.framework/Versions/3.10/lib/python3.10/ssl.py", line 1341, in do_handshake
    self._sslobj.do_handshake()
TimeoutError: _ssl.c:980: The handshake operation timed out

During handling of the above exception, another exception occurred:

Traceback (most recent call last):
  File "/usr/local/bin/bpytop", line 5009, in _checker
    with urllib.request.urlopen("https://github.com/aristocratos/bpytop/raw/master/bpytop.py", timeout=5) as source: # type: ignore
  File "/usr/local/Cellar/python@3.10/3.10.0_2/Frameworks/Python.framework/Versions/3.10/lib/python3.10/urllib/request.py", line 216, in urlopen
    return opener.open(url, data, timeout)
  File "/usr/local/Cellar/python@3.10/3.10.0_2/Frameworks/Python.framework/Versions/3.10/lib/python3.10/urllib/request.py", line 525, in open
    response = meth(req, response)
  File "/usr/local/Cellar/python@3.10/3.10.0_2/Frameworks/Python.framework/Versions/3.10/lib/python3.10/urllib/request.py", line 634, in http_response
    response = self.parent.error(
  File "/usr/local/Cellar/python@3.10/3.10.0_2/Frameworks/Python.framework/Versions/3.10/lib/python3.10/urllib/request.py", line 557, in error
    result = self._call_chain(*args)
  File "/usr/local/Cellar/python@3.10/3.10.0_2/Frameworks/Python.framework/Versions/3.10/lib/python3.10/urllib/request.py", line 496, in _call_chain
    result = func(*args)
  File "/usr/local/Cellar/python@3.10/3.10.0_2/Frameworks/Python.framework/Versions/3.10/lib/python3.10/urllib/request.py", line 749, in http_error_302
    return self.parent.open(new, timeout=req.timeout)
  File "/usr/local/Cellar/python@3.10/3.10.0_2/Frameworks/Python.framework/Versions/3.10/lib/python3.10/urllib/request.py", line 519, in open
    response = self._open(req, data)
  File "/usr/local/Cellar/python@3.10/3.10.0_2/Frameworks/Python.framework/Versions/3.10/lib/python3.10/urllib/request.py", line 536, in _open
    result = self._call_chain(self.handle_open, protocol, protocol +
  File "/usr/local/Cellar/python@3.10/3.10.0_2/Frameworks/Python.framework/Versions/3.10/lib/python3.10/urllib/request.py", line 496, in _call_chain
    result = func(*args)
  File "/usr/local/Cellar/python@3.10/3.10.0_2/Frameworks/Python.framework/Versions/3.10/lib/python3.10/urllib/request.py", line 1391, in https_open
    return self.do_open(http.client.HTTPSConnection, req,
  File "/usr/local/Cellar/python@3.10/3.10.0_2/Frameworks/Python.framework/Versions/3.10/lib/python3.10/urllib/request.py", line 1351, in do_open
    raise URLError(err)
urllib.error.URLError: <urlopen error _ssl.c:980: The handshake operation timed out>
22/10/21 (01:14:04) | ERROR: The read operation timed out
Traceback (most recent call last):
  File "/usr/local/bin/bpytop", line 5009, in _checker
    with urllib.request.urlopen("https://github.com/aristocratos/bpytop/raw/master/bpytop.py", timeout=5) as source: # type: ignore
  File "/usr/local/Cellar/python@3.10/3.10.0_2/Frameworks/Python.framework/Versions/3.10/lib/python3.10/urllib/request.py", line 216, in urlopen
    return opener.open(url, data, timeout)
  File "/usr/local/Cellar/python@3.10/3.10.0_2/Frameworks/Python.framework/Versions/3.10/lib/python3.10/urllib/request.py", line 519, in open
    response = self._open(req, data)
  File "/usr/local/Cellar/python@3.10/3.10.0_2/Frameworks/Python.framework/Versions/3.10/lib/python3.10/urllib/request.py", line 536, in _open
    result = self._call_chain(self.handle_open, protocol, protocol +
  File "/usr/local/Cellar/python@3.10/3.10.0_2/Frameworks/Python.framework/Versions/3.10/lib/python3.10/urllib/request.py", line 496, in _call_chain
    result = func(*args)
  File "/usr/local/Cellar/python@3.10/3.10.0_2/Frameworks/Python.framework/Versions/3.10/lib/python3.10/urllib/request.py", line 1391, in https_open
    return self.do_open(http.client.HTTPSConnection, req,
  File "/usr/local/Cellar/python@3.10/3.10.0_2/Frameworks/Python.framework/Versions/3.10/lib/python3.10/urllib/request.py", line 1352, in do_open
    r = h.getresponse()
  File "/usr/local/Cellar/python@3.10/3.10.0_2/Frameworks/Python.framework/Versions/3.10/lib/python3.10/http/client.py", line 1368, in getresponse
    response.begin()
  File "/usr/local/Cellar/python@3.10/3.10.0_2/Frameworks/Python.framework/Versions/3.10/lib/python3.10/http/client.py", line 317, in begin
    version, status, reason = self._read_status()
  File "/usr/local/Cellar/python@3.10/3.10.0_2/Frameworks/Python.framework/Versions/3.10/lib/python3.10/http/client.py", line 278, in _read_status
    line = str(self.fp.readline(_MAXLINE + 1), "iso-8859-1")
  File "/usr/local/Cellar/python@3.10/3.10.0_2/Frameworks/Python.framework/Versions/3.10/lib/python3.10/socket.py", line 705, in readinto
    return self._sock.recv_into(b)
  File "/usr/local/Cellar/python@3.10/3.10.0_2/Frameworks/Python.framework/Versions/3.10/lib/python3.10/ssl.py", line 1273, in recv_into
    return self.read(nbytes, buffer)
  File "/usr/local/Cellar/python@3.10/3.10.0_2/Frameworks/Python.framework/Versions/3.10/lib/python3.10/ssl.py", line 1129, in read
    return self._sslobj.read(len, buffer)
TimeoutError: The read operation timed out
22/10/21 (23:30:44) | ERROR: The read operation timed out
Traceback (most recent call last):
  File "/usr/local/bin/bpytop", line 5009, in _checker
    with urllib.request.urlopen("https://github.com/aristocratos/bpytop/raw/master/bpytop.py", timeout=5) as source: # type: ignore
  File "/usr/local/Cellar/python@3.10/3.10.0_2/Frameworks/Python.framework/Versions/3.10/lib/python3.10/urllib/request.py", line 216, in urlopen
    return opener.open(url, data, timeout)
  File "/usr/local/Cellar/python@3.10/3.10.0_2/Frameworks/Python.framework/Versions/3.10/lib/python3.10/urllib/request.py", line 519, in open
    response = self._open(req, data)
  File "/usr/local/Cellar/python@3.10/3.10.0_2/Frameworks/Python.framework/Versions/3.10/lib/python3.10/urllib/request.py", line 536, in _open
    result = self._call_chain(self.handle_open, protocol, protocol +
  File "/usr/local/Cellar/python@3.10/3.10.0_2/Frameworks/Python.framework/Versions/3.10/lib/python3.10/urllib/request.py", line 496, in _call_chain
    result = func(*args)
  File "/usr/local/Cellar/python@3.10/3.10.0_2/Frameworks/Python.framework/Versions/3.10/lib/python3.10/urllib/request.py", line 1391, in https_open
    return self.do_open(http.client.HTTPSConnection, req,
  File "/usr/local/Cellar/python@3.10/3.10.0_2/Frameworks/Python.framework/Versions/3.10/lib/python3.10/urllib/request.py", line 1352, in do_open
    r = h.getresponse()
  File "/usr/local/Cellar/python@3.10/3.10.0_2/Frameworks/Python.framework/Versions/3.10/lib/python3.10/http/client.py", line 1368, in getresponse
    response.begin()
  File "/usr/local/Cellar/python@3.10/3.10.0_2/Frameworks/Python.framework/Versions/3.10/lib/python3.10/http/client.py", line 317, in begin
    version, status, reason = self._read_status()
  File "/usr/local/Cellar/python@3.10/3.10.0_2/Frameworks/Python.framework/Versions/3.10/lib/python3.10/http/client.py", line 278, in _read_status
    line = str(self.fp.readline(_MAXLINE + 1), "iso-8859-1")
  File "/usr/local/Cellar/python@3.10/3.10.0_2/Frameworks/Python.framework/Versions/3.10/lib/python3.10/socket.py", line 705, in readinto
    return self._sock.recv_into(b)
  File "/usr/local/Cellar/python@3.10/3.10.0_2/Frameworks/Python.framework/Versions/3.10/lib/python3.10/ssl.py", line 1273, in recv_into
    return self.read(nbytes, buffer)
  File "/usr/local/Cellar/python@3.10/3.10.0_2/Frameworks/Python.framework/Versions/3.10/lib/python3.10/ssl.py", line 1129, in read
    return self._sslobj.read(len, buffer)
TimeoutError: The read operation timed out
23/10/21 (00:16:23) | ERROR: The read operation timed out
Traceback (most recent call last):
  File "/usr/local/bin/bpytop", line 5009, in _checker
    with urllib.request.urlopen("https://github.com/aristocratos/bpytop/raw/master/bpytop.py", timeout=5) as source: # type: ignore
  File "/usr/local/Cellar/python@3.10/3.10.0_2/Frameworks/Python.framework/Versions/3.10/lib/python3.10/urllib/request.py", line 216, in urlopen
    return opener.open(url, data, timeout)
  File "/usr/local/Cellar/python@3.10/3.10.0_2/Frameworks/Python.framework/Versions/3.10/lib/python3.10/urllib/request.py", line 519, in open
    response = self._open(req, data)
  File "/usr/local/Cellar/python@3.10/3.10.0_2/Frameworks/Python.framework/Versions/3.10/lib/python3.10/urllib/request.py", line 536, in _open
    result = self._call_chain(self.handle_open, protocol, protocol +
  File "/usr/local/Cellar/python@3.10/3.10.0_2/Frameworks/Python.framework/Versions/3.10/lib/python3.10/urllib/request.py", line 496, in _call_chain
    result = func(*args)
  File "/usr/local/Cellar/python@3.10/3.10.0_2/Frameworks/Python.framework/Versions/3.10/lib/python3.10/urllib/request.py", line 1391, in https_open
    return self.do_open(http.client.HTTPSConnection, req,
  File "/usr/local/Cellar/python@3.10/3.10.0_2/Frameworks/Python.framework/Versions/3.10/lib/python3.10/urllib/request.py", line 1352, in do_open
    r = h.getresponse()
  File "/usr/local/Cellar/python@3.10/3.10.0_2/Frameworks/Python.framework/Versions/3.10/lib/python3.10/http/client.py", line 1368, in getresponse
    response.begin()
  File "/usr/local/Cellar/python@3.10/3.10.0_2/Frameworks/Python.framework/Versions/3.10/lib/python3.10/http/client.py", line 317, in begin
    version, status, reason = self._read_status()
  File "/usr/local/Cellar/python@3.10/3.10.0_2/Frameworks/Python.framework/Versions/3.10/lib/python3.10/http/client.py", line 278, in _read_status
    line = str(self.fp.readline(_MAXLINE + 1), "iso-8859-1")
  File "/usr/local/Cellar/python@3.10/3.10.0_2/Frameworks/Python.framework/Versions/3.10/lib/python3.10/socket.py", line 705, in readinto
    return self._sock.recv_into(b)
  File "/usr/local/Cellar/python@3.10/3.10.0_2/Frameworks/Python.framework/Versions/3.10/lib/python3.10/ssl.py", line 1273, in recv_into
    return self.read(nbytes, buffer)
  File "/usr/local/Cellar/python@3.10/3.10.0_2/Frameworks/Python.framework/Versions/3.10/lib/python3.10/ssl.py", line 1129, in read
    return self._sslobj.read(len, buffer)
TimeoutError: The read operation timed out
23/10/21 (00:16:38) | ERROR: <urlopen error _ssl.c:980: The handshake operation timed out>
Traceback (most recent call last):
  File "/usr/local/Cellar/python@3.10/3.10.0_2/Frameworks/Python.framework/Versions/3.10/lib/python3.10/urllib/request.py", line 1348, in do_open
    h.request(req.get_method(), req.selector, req.data, headers,
  File "/usr/local/Cellar/python@3.10/3.10.0_2/Frameworks/Python.framework/Versions/3.10/lib/python3.10/http/client.py", line 1276, in request
    self._send_request(method, url, body, headers, encode_chunked)
  File "/usr/local/Cellar/python@3.10/3.10.0_2/Frameworks/Python.framework/Versions/3.10/lib/python3.10/http/client.py", line 1322, in _send_request
    self.endheaders(body, encode_chunked=encode_chunked)
  File "/usr/local/Cellar/python@3.10/3.10.0_2/Frameworks/Python.framework/Versions/3.10/lib/python3.10/http/client.py", line 1271, in endheaders
    self._send_output(message_body, encode_chunked=encode_chunked)
  File "/usr/local/Cellar/python@3.10/3.10.0_2/Frameworks/Python.framework/Versions/3.10/lib/python3.10/http/client.py", line 1031, in _send_output
    self.send(msg)
  File "/usr/local/Cellar/python@3.10/3.10.0_2/Frameworks/Python.framework/Versions/3.10/lib/python3.10/http/client.py", line 969, in send
    self.connect()
  File "/usr/local/Cellar/python@3.10/3.10.0_2/Frameworks/Python.framework/Versions/3.10/lib/python3.10/http/client.py", line 1448, in connect
    self.sock = self._context.wrap_socket(self.sock,
  File "/usr/local/Cellar/python@3.10/3.10.0_2/Frameworks/Python.framework/Versions/3.10/lib/python3.10/ssl.py", line 512, in wrap_socket
    return self.sslsocket_class._create(
  File "/usr/local/Cellar/python@3.10/3.10.0_2/Frameworks/Python.framework/Versions/3.10/lib/python3.10/ssl.py", line 1070, in _create
    self.do_handshake()
  File "/usr/local/Cellar/python@3.10/3.10.0_2/Frameworks/Python.framework/Versions/3.10/lib/python3.10/ssl.py", line 1341, in do_handshake
    self._sslobj.do_handshake()
TimeoutError: _ssl.c:980: The handshake operation timed out

During handling of the above exception, another exception occurred:

Traceback (most recent call last):
  File "/usr/local/bin/bpytop", line 5009, in _checker
    with urllib.request.urlopen("https://github.com/aristocratos/bpytop/raw/master/bpytop.py", timeout=5) as source: # type: ignore
  File "/usr/local/Cellar/python@3.10/3.10.0_2/Frameworks/Python.framework/Versions/3.10/lib/python3.10/urllib/request.py", line 216, in urlopen
    return opener.open(url, data, timeout)
  File "/usr/local/Cellar/python@3.10/3.10.0_2/Frameworks/Python.framework/Versions/3.10/lib/python3.10/urllib/request.py", line 525, in open
    response = meth(req, response)
  File "/usr/local/Cellar/python@3.10/3.10.0_2/Frameworks/Python.framework/Versions/3.10/lib/python3.10/urllib/request.py", line 634, in http_response
    response = self.parent.error(
  File "/usr/local/Cellar/python@3.10/3.10.0_2/Frameworks/Python.framework/Versions/3.10/lib/python3.10/urllib/request.py", line 557, in error
    result = self._call_chain(*args)
  File "/usr/local/Cellar/python@3.10/3.10.0_2/Frameworks/Python.framework/Versions/3.10/lib/python3.10/urllib/request.py", line 496, in _call_chain
    result = func(*args)
  File "/usr/local/Cellar/python@3.10/3.10.0_2/Frameworks/Python.framework/Versions/3.10/lib/python3.10/urllib/request.py", line 749, in http_error_302
    return self.parent.open(new, timeout=req.timeout)
  File "/usr/local/Cellar/python@3.10/3.10.0_2/Frameworks/Python.framework/Versions/3.10/lib/python3.10/urllib/request.py", line 519, in open
    response = self._open(req, data)
  File "/usr/local/Cellar/python@3.10/3.10.0_2/Frameworks/Python.framework/Versions/3.10/lib/python3.10/urllib/request.py", line 536, in _open
    result = self._call_chain(self.handle_open, protocol, protocol +
  File "/usr/local/Cellar/python@3.10/3.10.0_2/Frameworks/Python.framework/Versions/3.10/lib/python3.10/urllib/request.py", line 496, in _call_chain
    result = func(*args)
  File "/usr/local/Cellar/python@3.10/3.10.0_2/Frameworks/Python.framework/Versions/3.10/lib/python3.10/urllib/request.py", line 1391, in https_open
    return self.do_open(http.client.HTTPSConnection, req,
  File "/usr/local/Cellar/python@3.10/3.10.0_2/Frameworks/Python.framework/Versions/3.10/lib/python3.10/urllib/request.py", line 1351, in do_open
    raise URLError(err)
urllib.error.URLError: <urlopen error _ssl.c:980: The handshake operation timed out>
24/10/21 (10:10:39) | ERROR: <urlopen error timed out>
Traceback (most recent call last):
  File "/usr/local/Cellar/python@3.10/3.10.0_2/Frameworks/Python.framework/Versions/3.10/lib/python3.10/urllib/request.py", line 1348, in do_open
    h.request(req.get_method(), req.selector, req.data, headers,
  File "/usr/local/Cellar/python@3.10/3.10.0_2/Frameworks/Python.framework/Versions/3.10/lib/python3.10/http/client.py", line 1276, in request
    self._send_request(method, url, body, headers, encode_chunked)
  File "/usr/local/Cellar/python@3.10/3.10.0_2/Frameworks/Python.framework/Versions/3.10/lib/python3.10/http/client.py", line 1322, in _send_request
    self.endheaders(body, encode_chunked=encode_chunked)
  File "/usr/local/Cellar/python@3.10/3.10.0_2/Frameworks/Python.framework/Versions/3.10/lib/python3.10/http/client.py", line 1271, in endheaders
    self._send_output(message_body, encode_chunked=encode_chunked)
  File "/usr/local/Cellar/python@3.10/3.10.0_2/Frameworks/Python.framework/Versions/3.10/lib/python3.10/http/client.py", line 1031, in _send_output
    self.send(msg)
  File "/usr/local/Cellar/python@3.10/3.10.0_2/Frameworks/Python.framework/Versions/3.10/lib/python3.10/http/client.py", line 969, in send
    self.connect()
  File "/usr/local/Cellar/python@3.10/3.10.0_2/Frameworks/Python.framework/Versions/3.10/lib/python3.10/http/client.py", line 1441, in connect
    super().connect()
  File "/usr/local/Cellar/python@3.10/3.10.0_2/Frameworks/Python.framework/Versions/3.10/lib/python3.10/http/client.py", line 940, in connect
    self.sock = self._create_connection(
  File "/usr/local/Cellar/python@3.10/3.10.0_2/Frameworks/Python.framework/Versions/3.10/lib/python3.10/socket.py", line 845, in create_connection
    raise err
  File "/usr/local/Cellar/python@3.10/3.10.0_2/Frameworks/Python.framework/Versions/3.10/lib/python3.10/socket.py", line 833, in create_connection
    sock.connect(sa)
TimeoutError: timed out

During handling of the above exception, another exception occurred:

Traceback (most recent call last):
  File "/usr/local/bin/bpytop", line 5009, in _checker
    with urllib.request.urlopen("https://github.com/aristocratos/bpytop/raw/master/bpytop.py", timeout=5) as source: # type: ignore
  File "/usr/local/Cellar/python@3.10/3.10.0_2/Frameworks/Python.framework/Versions/3.10/lib/python3.10/urllib/request.py", line 216, in urlopen
    return opener.open(url, data, timeout)
  File "/usr/local/Cellar/python@3.10/3.10.0_2/Frameworks/Python.framework/Versions/3.10/lib/python3.10/urllib/request.py", line 519, in open
    response = self._open(req, data)
  File "/usr/local/Cellar/python@3.10/3.10.0_2/Frameworks/Python.framework/Versions/3.10/lib/python3.10/urllib/request.py", line 536, in _open
    result = self._call_chain(self.handle_open, protocol, protocol +
  File "/usr/local/Cellar/python@3.10/3.10.0_2/Frameworks/Python.framework/Versions/3.10/lib/python3.10/urllib/request.py", line 496, in _call_chain
    result = func(*args)
  File "/usr/local/Cellar/python@3.10/3.10.0_2/Frameworks/Python.framework/Versions/3.10/lib/python3.10/urllib/request.py", line 1391, in https_open
    return self.do_open(http.client.HTTPSConnection, req,
  File "/usr/local/Cellar/python@3.10/3.10.0_2/Frameworks/Python.framework/Versions/3.10/lib/python3.10/urllib/request.py", line 1351, in do_open
    raise URLError(err)
urllib.error.URLError: <urlopen error timed out>
26/10/21 (20:27:24) | ERROR: <urlopen error _ssl.c:980: The handshake operation timed out>
Traceback (most recent call last):
  File "/usr/local/Cellar/python@3.10/3.10.0_2/Frameworks/Python.framework/Versions/3.10/lib/python3.10/urllib/request.py", line 1348, in do_open
    h.request(req.get_method(), req.selector, req.data, headers,
  File "/usr/local/Cellar/python@3.10/3.10.0_2/Frameworks/Python.framework/Versions/3.10/lib/python3.10/http/client.py", line 1276, in request
    self._send_request(method, url, body, headers, encode_chunked)
  File "/usr/local/Cellar/python@3.10/3.10.0_2/Frameworks/Python.framework/Versions/3.10/lib/python3.10/http/client.py", line 1322, in _send_request
    self.endheaders(body, encode_chunked=encode_chunked)
  File "/usr/local/Cellar/python@3.10/3.10.0_2/Frameworks/Python.framework/Versions/3.10/lib/python3.10/http/client.py", line 1271, in endheaders
    self._send_output(message_body, encode_chunked=encode_chunked)
  File "/usr/local/Cellar/python@3.10/3.10.0_2/Frameworks/Python.framework/Versions/3.10/lib/python3.10/http/client.py", line 1031, in _send_output
    self.send(msg)
  File "/usr/local/Cellar/python@3.10/3.10.0_2/Frameworks/Python.framework/Versions/3.10/lib/python3.10/http/client.py", line 969, in send
    self.connect()
  File "/usr/local/Cellar/python@3.10/3.10.0_2/Frameworks/Python.framework/Versions/3.10/lib/python3.10/http/client.py", line 1448, in connect
    self.sock = self._context.wrap_socket(self.sock,
  File "/usr/local/Cellar/python@3.10/3.10.0_2/Frameworks/Python.framework/Versions/3.10/lib/python3.10/ssl.py", line 512, in wrap_socket
    return self.sslsocket_class._create(
  File "/usr/local/Cellar/python@3.10/3.10.0_2/Frameworks/Python.framework/Versions/3.10/lib/python3.10/ssl.py", line 1070, in _create
    self.do_handshake()
  File "/usr/local/Cellar/python@3.10/3.10.0_2/Frameworks/Python.framework/Versions/3.10/lib/python3.10/ssl.py", line 1341, in do_handshake
    self._sslobj.do_handshake()
TimeoutError: _ssl.c:980: The handshake operation timed out

During handling of the above exception, another exception occurred:

Traceback (most recent call last):
  File "/usr/local/bin/bpytop", line 5009, in _checker
    with urllib.request.urlopen("https://github.com/aristocratos/bpytop/raw/master/bpytop.py", timeout=5) as source: # type: ignore
  File "/usr/local/Cellar/python@3.10/3.10.0_2/Frameworks/Python.framework/Versions/3.10/lib/python3.10/urllib/request.py", line 216, in urlopen
    return opener.open(url, data, timeout)
  File "/usr/local/Cellar/python@3.10/3.10.0_2/Frameworks/Python.framework/Versions/3.10/lib/python3.10/urllib/request.py", line 525, in open
    response = meth(req, response)
  File "/usr/local/Cellar/python@3.10/3.10.0_2/Frameworks/Python.framework/Versions/3.10/lib/python3.10/urllib/request.py", line 634, in http_response
    response = self.parent.error(
  File "/usr/local/Cellar/python@3.10/3.10.0_2/Frameworks/Python.framework/Versions/3.10/lib/python3.10/urllib/request.py", line 557, in error
    result = self._call_chain(*args)
  File "/usr/local/Cellar/python@3.10/3.10.0_2/Frameworks/Python.framework/Versions/3.10/lib/python3.10/urllib/request.py", line 496, in _call_chain
    result = func(*args)
  File "/usr/local/Cellar/python@3.10/3.10.0_2/Frameworks/Python.framework/Versions/3.10/lib/python3.10/urllib/request.py", line 749, in http_error_302
    return self.parent.open(new, timeout=req.timeout)
  File "/usr/local/Cellar/python@3.10/3.10.0_2/Frameworks/Python.framework/Versions/3.10/lib/python3.10/urllib/request.py", line 519, in open
    response = self._open(req, data)
  File "/usr/local/Cellar/python@3.10/3.10.0_2/Frameworks/Python.framework/Versions/3.10/lib/python3.10/urllib/request.py", line 536, in _open
    result = self._call_chain(self.handle_open, protocol, protocol +
  File "/usr/local/Cellar/python@3.10/3.10.0_2/Frameworks/Python.framework/Versions/3.10/lib/python3.10/urllib/request.py", line 496, in _call_chain
    result = func(*args)
  File "/usr/local/Cellar/python@3.10/3.10.0_2/Frameworks/Python.framework/Versions/3.10/lib/python3.10/urllib/request.py", line 1391, in https_open
    return self.do_open(http.client.HTTPSConnection, req,
  File "/usr/local/Cellar/python@3.10/3.10.0_2/Frameworks/Python.framework/Versions/3.10/lib/python3.10/urllib/request.py", line 1351, in do_open
    raise URLError(err)
urllib.error.URLError: <urlopen error _ssl.c:980: The handshake operation timed out>
25/11/21 (22:18:51) | ERROR: The read operation timed out
Traceback (most recent call last):
  File "/usr/local/bin/bpytop", line 5009, in _checker
    with urllib.request.urlopen("https://github.com/aristocratos/bpytop/raw/master/bpytop.py", timeout=5) as source: # type: ignore
  File "/usr/local/Cellar/python@3.10/3.10.0_2/Frameworks/Python.framework/Versions/3.10/lib/python3.10/urllib/request.py", line 216, in urlopen
    return opener.open(url, data, timeout)
  File "/usr/local/Cellar/python@3.10/3.10.0_2/Frameworks/Python.framework/Versions/3.10/lib/python3.10/urllib/request.py", line 525, in open
    response = meth(req, response)
  File "/usr/local/Cellar/python@3.10/3.10.0_2/Frameworks/Python.framework/Versions/3.10/lib/python3.10/urllib/request.py", line 634, in http_response
    response = self.parent.error(
  File "/usr/local/Cellar/python@3.10/3.10.0_2/Frameworks/Python.framework/Versions/3.10/lib/python3.10/urllib/request.py", line 557, in error
    result = self._call_chain(*args)
  File "/usr/local/Cellar/python@3.10/3.10.0_2/Frameworks/Python.framework/Versions/3.10/lib/python3.10/urllib/request.py", line 496, in _call_chain
    result = func(*args)
  File "/usr/local/Cellar/python@3.10/3.10.0_2/Frameworks/Python.framework/Versions/3.10/lib/python3.10/urllib/request.py", line 749, in http_error_302
    return self.parent.open(new, timeout=req.timeout)
  File "/usr/local/Cellar/python@3.10/3.10.0_2/Frameworks/Python.framework/Versions/3.10/lib/python3.10/urllib/request.py", line 519, in open
    response = self._open(req, data)
  File "/usr/local/Cellar/python@3.10/3.10.0_2/Frameworks/Python.framework/Versions/3.10/lib/python3.10/urllib/request.py", line 536, in _open
    result = self._call_chain(self.handle_open, protocol, protocol +
  File "/usr/local/Cellar/python@3.10/3.10.0_2/Frameworks/Python.framework/Versions/3.10/lib/python3.10/urllib/request.py", line 496, in _call_chain
    result = func(*args)
  File "/usr/local/Cellar/python@3.10/3.10.0_2/Frameworks/Python.framework/Versions/3.10/lib/python3.10/urllib/request.py", line 1391, in https_open
    return self.do_open(http.client.HTTPSConnection, req,
  File "/usr/local/Cellar/python@3.10/3.10.0_2/Frameworks/Python.framework/Versions/3.10/lib/python3.10/urllib/request.py", line 1352, in do_open
    r = h.getresponse()
  File "/usr/local/Cellar/python@3.10/3.10.0_2/Frameworks/Python.framework/Versions/3.10/lib/python3.10/http/client.py", line 1368, in getresponse
    response.begin()
  File "/usr/local/Cellar/python@3.10/3.10.0_2/Frameworks/Python.framework/Versions/3.10/lib/python3.10/http/client.py", line 317, in begin
    version, status, reason = self._read_status()
  File "/usr/local/Cellar/python@3.10/3.10.0_2/Frameworks/Python.framework/Versions/3.10/lib/python3.10/http/client.py", line 278, in _read_status
    line = str(self.fp.readline(_MAXLINE + 1), "iso-8859-1")
  File "/usr/local/Cellar/python@3.10/3.10.0_2/Frameworks/Python.framework/Versions/3.10/lib/python3.10/socket.py", line 705, in readinto
    return self._sock.recv_into(b)
  File "/usr/local/Cellar/python@3.10/3.10.0_2/Frameworks/Python.framework/Versions/3.10/lib/python3.10/ssl.py", line 1273, in recv_into
    return self.read(nbytes, buffer)
  File "/usr/local/Cellar/python@3.10/3.10.0_2/Frameworks/Python.framework/Versions/3.10/lib/python3.10/ssl.py", line 1129, in read
    return self._sslobj.read(len, buffer)
TimeoutError: The read operation timed out
16/12/21 (20:47:20) | ERROR: Data collection thread failed with exception: Precision not allowed in integer format specifier
Traceback (most recent call last):
  File "/usr/local/bin/bpytop", line 2939, in _runner
    collector._draw()
  File "/usr/local/bin/bpytop", line 3971, in _draw
    ProcBox._draw_fg()
  File "/usr/local/bin/bpytop", line 2751, in _draw_fg
    (f'{proc.details["threads"]:^{iw}.{iw2}}' if expand > 0 else "") + (f'{proc.details["nice"]:^{iw}.{iw2}}' if expand > 1 else "") +
ValueError: Precision not allowed in integer format specifier
16/12/21 (20:47:21) | WARNING: Exiting with errorcode (1). Runtime 0:00:17 

31/12/21 (02:19:35) | ERROR: Data collection thread failed with exception: Precision not allowed in integer format specifier
Traceback (most recent call last):
  File "/usr/local/bin/bpytop", line 2959, in _runner
    collector._draw()
  File "/usr/local/bin/bpytop", line 3991, in _draw
    ProcBox._draw_fg()
  File "/usr/local/bin/bpytop", line 2771, in _draw_fg
    (f'{proc.details["threads"]:^{iw}.{iw2}}' if expand > 0 else "") + (f'{proc.details["nice"]:^{iw}.{iw2}}' if expand > 1 else "") +
ValueError: Precision not allowed in integer format specifier
31/12/21 (02:19:38) | WARNING: Exiting with errorcode (1). Runtime 0:01:20 

31/12/21 (02:19:51) | ERROR: Data collection thread failed with exception: Precision not allowed in integer format specifier
Traceback (most recent call last):
  File "/usr/local/bin/bpytop", line 2959, in _runner
    collector._draw()
  File "/usr/local/bin/bpytop", line 3991, in _draw
    ProcBox._draw_fg()
  File "/usr/local/bin/bpytop", line 2771, in _draw_fg
    (f'{proc.details["threads"]:^{iw}.{iw2}}' if expand > 0 else "") + (f'{proc.details["nice"]:^{iw}.{iw2}}' if expand > 1 else "") +
ValueError: Precision not allowed in integer format specifier
31/12/21 (02:19:55) | WARNING: Exiting with errorcode (1). Runtime 0:00:11 

28/04/22 (20:06:34) | ERROR: Exception when sending signal 2 to pid 205
28/04/22 (20:06:34) | ERROR: [Errno 1] Operation not permitted
Traceback (most recent call last):
  File "/usr/local/bin/bpytop", line 5479, in process_keys
    os.kill(pid, sig)
PermissionError: [Errno 1] Operation not permitted
